Workbook

Sheet TACg
A1: Generaciones | B1: 0 | C1: 1 | D1: 2 | E1: 3 | F1: 4 | G1: 5 | H1: 6 | I1: 7 | J1: 8 | K1: 9 | L1: 10 | M1: 11 | O1: TACg | P1: TAC
A2: Manual | B2: 1 | C2: 2 | D2: 4 | E2: 10 | F2: 20 | G2: 40 | H2: 36 | I2: 28 | J2: 16 | K2: 2 | L2: 0 | M2: 0 | O2: =CONCATENATE("G",MATCH(MAX(C2:L2),C2:L2,0)-1,"(",MAX(C2:L2),")") -> G4(40) | P2: =SUM(B2:M2) -> 159
A3: 3D Slicer | B3: 1 | C3: 2 | D3: 4 | E3: 9 | F3: 14 | G3: 9 | H3: 4 | I3: 4 | J3: 0 | K3: 0 | L3: 0 | M3: 0 | O3: =CONCATENATE("G",MATCH(MAX(C3:L3),C3:L3,0)-1,"(",MAX(C3:L3),")") -> G3(14) | P3: =SUM(B3:M3) -> 47
A4: Label BFS | B4: ='Label BFS'!R2 -> 1 | C4: ='Label BFS'!S2 -> 2 | D4: ='Label BFS'!T2 -> 3 | E4: ='Label BFS'!U2 -> 6 | F4: ='Label BFS'!V2 -> 7 | G4: ='Label BFS'!W2 -> 5 | H4: ='Label BFS'!X2 -> 3 | I4: ='Label BFS'!Y2 -> 2 | ... M4: ='Label BFS'!AC2 -> 0 | O4: =CONCATENATE("G",MATCH(MAX(C4:L4),C4:L4,0)-1,"(",MAX(C4:L4),")") -> G3(7) | P4: =SUM(B4:M4) -> 32
A5: Swin UNETR | B5: 1 | C5: 3 | D5: 4 | E5: 6 | F5: 8 | G5: 2 | H5: 1 | I5: 0 | J5: 0 | K5: 0 | L5: 0 | M5: 0 | O5: =CONCATENATE("G",MATCH(MAX(C5:L5),C5:L5,0)-1,"(",MAX(C5:L5),")") -> G3(8) | P5: =SUM(B5:M5) -> 25
A7: Clipped | B7: =Clip!S2 -> 1 | C7: =Clip!T2 -> 2 | D7: =Clip!U2 -> 4 | E7: =Clip!V2 -> 6 | F7: =Clip!W2 -> 7 | G7: =Clip!X2 -> 6 | H7: =Clip!Y2 -> 3 | I7: =Clip!Z2 -> 2 | ... M7: =Clip!AD2 -> 0 | O7: =CONCATENATE("G",MATCH(MAX(C7:L7),C7:L7,0)-1,"(",MAX(C7:L7),")") -> G3(7) | P7: =SUM(B7:M7) -> 33
A8: Clipped_Normalized | B8: =Clip_Norm!S2 -> 1 | C8: =Clip_Norm!T2 -> 2 | D8: =Clip_Norm!U2 -> 4 | E8: =Clip_Norm!V2 -> 6 | F8: =Clip_Norm!W2 -> 7 | G8: =Clip_Norm!X2 -> 6 | H8: =Clip_Norm!Y2 -> 4 | I8: =Clip_Norm!Z2 -> 2 | ... M8: =Clip_Norm!AD2 -> 0 | O8: =CONCATENATE("G",MATCH(MAX(C8:L8),C8:L8,0)-1,"(",MAX(C8:L8),")") -> G3(7) | P8: =SUM(B8:M8) -> 35
A9: Clipped_Normalized_Padded | B9: =Clip_Norm_Pad!S2 -> 1 | C9: =Clip_Norm_Pad!T2 -> 2 | D9: =Clip_Norm_Pad!U2 -> 4 | E9: =Clip_Norm_Pad!V2 -> 7 | F9: =Clip_Norm_Pad!W2 -> 9 | G9: =Clip_Norm_Pad!X2 -> 8 | H9: =Clip_Norm_Pad!Y2 -> 5 | I9: =Clip_Norm_Pad!Z2 -> 3 | ... M9: =Clip_Norm_Pad!AD2 -> 1 | O9: =CONCATENATE("G",MATCH(MAX(C9:L9),C9:L9,0)-1,"(",MAX(C9:L9),")") -> G3(9) | P9: =SUM(B9:M9) -> 43
A10: Clipped_Padded | B10: =Clip_Pad!S2 -> 1 | C10: =Clip_Pad!T2 -> 2 | D10: =Clip_Pad!U2 -> 4 | E10: =Clip_Pad!V2 -> 7 | F10: =Clip_Pad!W2 -> 9 | G10: =Clip_Pad!X2 -> 8 | H10: =Clip_Pad!Y2 -> 5 | I10: =Clip_Pad!Z2 -> 2 | ... M10: =Clip_Pad!AD2 -> 0 | O10: =CONCATENATE("G",MATCH(MAX(C10:L10),C10:L10,0)-1,"(",MAX(C10:L10),")") -> G3(9) | P10: =SUM(B10:M10) -> 41
A11: Clipped_Smoothed | B11: =Clip_Smo!S2 -> 1 | C11: =Clip_Smo!T2 -> 2 | D11: =Clip_Smo!U2 -> 3 | E11: =Clip_Smo!V2 -> 5 | F11: =Clip_Smo!W2 -> 4 | G11: =Clip_Smo!X2 -> 2 | H11: =Clip_Smo!Y2 -> 1 | I11: =Clip_Smo!Z2 -> 1 | ... M11: =Clip_Smo!AD2 -> 0 | O11: =CONCATENATE("G",MATCH(MAX(C11:L11),C11:L11,0)-1,"(",MAX(C11:L11),")") -> G2(5) | P11: =SUM(B11:M11) -> 20
A12: Clipped_Smoothed_Normalized | B12: =Clip_Smo_Norm!S2 -> 1 | C12: =Clip_Smo_Norm!T2 -> 2 | D12: =Clip_Smo_Norm!U2 -> 4 | E12: =Clip_Smo_Norm!V2 -> 5 | F12: =Clip_Smo_Norm!W2 -> 4 | G12: =Clip_Smo_Norm!X2 -> 2 | H12: =Clip_Smo_Norm!Y2 -> 1 | I12: =Clip_Smo_Norm!Z2 -> 1 | ... M12: =Clip_Smo_Norm!AD2 -> 0 | O12: =CONCATENATE("G",MATCH(MAX(C12:L12),C12:L12,0)-1,"(",MAX(C12:L12),")") -> G2(5) | P12: =SUM(B12:M12) -> 21
A13: Clipped_Smoothed_Normalized_Padded | B13: =Clip_Smo_Norm_Padd!S2 -> 1 | C13: =Clip_Smo_Norm_Padd!T2 -> 2 | D13: =Clip_Smo_Norm_Padd!U2 -> 4 | E13: =Clip_Smo_Norm_Padd!V2 -> 6 | F13: =Clip_Smo_Norm_Padd!W2 -> 5 | G13: =Clip_Smo_Norm_Padd!X2 -> 3 | H13: =Clip_Smo_Norm_Padd!Y2 -> 1 | I13: =Clip_Smo_Norm_Padd!Z2 -> 1 | ... M13: =Clip_Smo_Norm_Padd!AD2 -> 0 | O13: =CONCATENATE("G",MATCH(MAX(C13:L13),C13:L13,0)-1,"(",MAX(C13:L13),")") -> G2(6) | P13: =SUM(B13:M13) -> 24
A14: Clipped_Smoothed_Padded | B14: =Clip_Smo_Pad!S2 -> 1 | C14: =Clip_Smo_Pad!T2 -> 2 | D14: =Clip_Smo_Pad!U2 -> 4 | E14: =Clip_Smo_Pad!V2 -> 6 | F14: =Clip_Smo_Pad!W2 -> 5 | G14: =Clip_Smo_Pad!X2 -> 3 | H14: =Clip_Smo_Pad!Y2 -> 1 | I14: =Clip_Smo_Pad!Z2 -> 1 | ... M14: =Clip_Smo_Pad!AD2 -> 0 | O14: =CONCATENATE("G",MATCH(MAX(C14:L14),C14:L14,0)-1,"(",MAX(C14:L14),")") -> G2(6) | P14: =SUM(B14:M14) -> 24
A15: Normalized | B15: =Norm!S2 -> 1 | C15: =Norm!T2 -> 2 | D15: =Norm!U2 -> 4 | E15: =Norm!V2 -> 6 | F15: =Norm!W2 -> 7 | G15: =Norm!X2 -> 6 | H15: =Norm!Y2 -> 3 | I15: =Norm!Z2 -> 2 | ... M15: =Norm!AD2 -> 1 | O15: =CONCATENATE("G",MATCH(MAX(C15:L15),C15:L15,0)-1,"(",MAX(C15:L15),")") -> G3(7) | P15: =SUM(B15:M15) -> 35
A16: Normalized_Padded | B16: =Norm_Pad!S2 -> 1 | C16: =Norm_Pad!T2 -> 2 | D16: =Norm_Pad!U2 -> 4 | E16: =Norm_Pad!V2 -> 7 | F16: =Norm_Pad!W2 -> 10 | G16: =Norm_Pad!X2 -> 8 | H16: =Norm_Pad!Y2 -> 5 | I16: =Norm_Pad!Z2 -> 2 | ... M16: =Norm_Pad!AD2 -> 1 | O16: =CONCATENATE("G",MATCH(MAX(C16:L16),C16:L16,0)-1,"(",MAX(C16:L16),")") -> G3(10) | P16: =SUM(B16:M16) -> 43
A17: Padded | B17: =Pad!S2 -> 1 | C17: =Pad!T2 -> 2 | D17: =Pad!U2 -> 4 | E17: =Pad!V2 -> 7 | F17: =Pad!W2 -> 9 | G17: =Pad!X2 -> 8 | H17: =Pad!Y2 -> 5 | I17: =Pad!Z2 -> 2 | ... M17: =Pad!AD2 -> 1 | O17: =CONCATENATE("G",MATCH(MAX(C17:L17),C17:L17,0)-1,"(",MAX(C17:L17),")") -> G3(9) | P17: =SUM(B17:M17) -> 42
A18: Smoothed | B18: =Smo!S2 -> 1 | C18: =Smo!T2 -> 2 | D18: =Smo!U2 -> 4 | E18: =Smo!V2 -> 5 | F18: =Smo!W2 -> 4 | G18: =Smo!X2 -> 2 | H18: =Smo!Y2 -> 1 | I18: =Smo!Z2 -> 1 | ... M18: =Smo!AD2 -> 0 | O18: =CONCATENATE("G",MATCH(MAX(C18:L18),C18:L18,0)-1,"(",MAX(C18:L18),")") -> G2(5) | P18: =SUM(B18:M18) -> 23
A19: Smoothed_Normalized | B19: =Smo_Norm!S2 -> 1 | C19: =Smo_Norm!T2 -> 2 | D19: =Smo_Norm!U2 -> 4 | E19: =Smo_Norm!V2 -> 5 | F19: =Smo_Norm!W2 -> 4 | G19: =Smo_Norm!X2 -> 2 | H19: =Smo_Norm!Y2 -> 1 | I19: =Smo_Norm!Z2 -> 1 | ... M19: =Smo_Norm!AD2 -> 0 | O19: =CONCATENATE("G",MATCH(MAX(C19:L19),C19:L19,0)-1,"(",MAX(C19:L19),")") -> G2(5) | P19: =SUM(B19:M19) -> 21
A20: Smoothed_Normalized_Padded | B20: =Smo__Norm_Pad!S2 -> 1 | C20: =Smo__Norm_Pad!T2 -> 2 | D20: =Smo__Norm_Pad!U2 -> 4 | E20: =Smo__Norm_Pad!V2 -> 6 | F20: =Smo__Norm_Pad!W2 -> 5 | G20: =Smo__Norm_Pad!X2 -> 3 | H20: =Smo__Norm_Pad!Y2 -> 1 | I20: =Smo__Norm_Pad!Z2 -> 1 | ... M20: =Smo__Norm_Pad!AD2 -> 0 | O20: =CONCATENATE("G",MATCH(MAX(C20:L20),C20:L20,0)-1,"(",MAX(C20:L20),")") -> G2(6) | P20: =SUM(B20:M20) -> 24
A21: Smoothed_Padded | B21: =Smo_Pad!S2 -> 1 | C21: =Smo_Pad!T2 -> 2 | D21: =Smo_Pad!U2 -> 4 | E21: =Smo_Pad!V2 -> 6 | F21: =Smo_Pad!W2 -> 5 | G21: =Smo_Pad!X2 -> 3 | H21: =Smo_Pad!Y2 -> 1 | I21: =Smo_Pad!Z2 -> 1 | ... M21: =Smo_Pad!AD2 -> 0 | O21: =CONCATENATE("G",MATCH(MAX(C21:L21),C21:L21,0)-1,"(",MAX(C21:L21),")") -> G2(6) | P21: =SUM(B21:M21) -> 24

Sheet Label BFS
A1: Generaciones | B1: 0 | C1: 1 | D1: 2 | E1: 3 | F1: 4 | G1: 5 | H1: 6 | I1: 7 | J1: 8 | K1: 9 | L1: 10 | N1: Peak | O1: TAC | R1: 0 | S1: 1 | T1: 2 | U1: 3 | V1: 4 | W1: 5 | X1: 6 | Y1: 7 | Z1: 8 | AA1: 9 | AB1: 10
A2: ATM_001 | B2: 1 | C2: 2 | D2: 4 | E2: 8 | F2: 8 | G2: 2 | H2: 4 | I2: 0 | J2: 0 | K2: 0 | L2: 0 | N2: =CONCATENATE("G",MATCH(MAX(B2:K2),B2:K2,0)-1,"(",MAX(B2:K2),")") -> G3(8) | O2: =SUM(B2:K2) -> 29 | Q2: Promedio | R2: =ROUNDUP(AVERAGE(B2:B151), 0) -> 1 | S2: =ROUNDUP(AVERAGE(C2:C151), 0) -> 2 | T2: =ROUNDUP(AVERAGE(D2:D151), 0) -> 3 | U2: =ROUNDUP(AVERAGE(E2:E151), 0) -> 6 | V2: =ROUNDUP(AVERAGE(F2:F151), 0) -> 7 | W2: =ROUNDUP(AVERAGE(G2:G151), 0) -> 5 | X2: =ROUNDUP(AVERAGE(H2:H151), 0) -> 3 | Y2: =ROUNDUP(AVERAGE(I2:I151), 0) -> 2 | ... AB2: =ROUNDUP(AVERAGE(L2:L151), 0) -> 1
A3: ATM_002 | B3: 1 | C3: 2 | D3: 5 | E3: 6 | F3: 7 | G3: 3 | H3: 2 | I3: 4 | J3: 0 | K3: 0 | L3: 0 | N3: =CONCATENATE("G",MATCH(MAX(B3:K3),B3:K3,0)-1,"(",MAX(B3:K3),")") -> G4(7) | O3: =SUM(B3:K3) -> 30 | Q3: Max | R3: =MAX(B2:B151) -> 1 | S3: =MAX(C2:C151) -> 5 | T3: =MAX(D2:D151) -> 5 | U3: =MAX(E2:E151) -> 10 | V3: =MAX(F2:F151) -> 22 | W3: =MAX(G2:G151) -> 34 | X3: =MAX(H2:H151) -> 33 | Y3: =MAX(I2:I151) -> 17 | ... AB3: =MAX(L2:L151) -> 4
A4: ATM_003 | B4: 1 | C4: 1 | D4: 2 | E4: 4 | F4: 8 | G4: 7 | H4: 2 | I4: 0 | J4: 0 | K4: 0 | L4: 0 | N4: =CONCATENATE("G",MATCH(MAX(B4:K4),B4:K4,0)-1,"(",MAX(B4:K4),")") -> G4(8) | O4: =SUM(B4:K4) -> 25 | Q4: Moda | R4: =_xlfn.MODE.SNGL(B2:B151) -> 1 | S4: =_xlfn.MODE.SNGL(C2:C151) -> 2 | T4: =_xlfn.MODE.SNGL(D2:D151) -> 4 | U4: =_xlfn.MODE.SNGL(E2:E151) -> 9 | V4: =_xlfn.MODE.SNGL(F2:F151) -> 0 | W4: =_xlfn.MODE.SNGL(G2:G151) -> 0 | X4: =_xlfn.MODE.SNGL(H2:H151) -> 0 | Y4: =_xlfn.MODE.SNGL(I2:I151) -> 0 | ... AB4: =_xlfn.MODE.SNGL(L2:L151) -> 0
A5: ATM_004 | B5: 1 | C5: 2 | D5: 4 | E5: 8 | F5: 16 | G5: 30 | H5: 24 | I5: 8 | J5: 8 | K5: 6 | L5: 0 | N5: =CONCATENATE("G",MATCH(MAX(B5:K5),B5:K5,0)-1,"(",MAX(B5:K5),")") -> G5(30) | O5: =SUM(B5:K5) -> 107 | Q5: Mediana | R5: =MEDIAN(B2:B151) -> 1 | S5: =MEDIAN(C2:C151) -> 2 | T5: =MEDIAN(D2:D151) -> 4 | U5: =MEDIAN(E2:E151) -> 6 | V5: =MEDIAN(F2:F151) -> 6 | W5: =MEDIAN(G2:G151) -> 3 | X5: =MEDIAN(H2:H151) -> 1 | Y5: =MEDIAN(I2:I151) -> 0 | ... AB5: =MEDIAN(L2:L151) -> 0
A6: ATM_005 | B6: 1 | C6: 2 | D6: 3 | E6: 6 | F6: 6 | G6: 6 | H6: 3 | I6: 1 | J6: 0 | K6: 0 | L6: 0 | N6: =CONCATENATE("G",MATCH(MAX(B6:K6),B6:K6,0)-1,"(",MAX(B6:K6),")") -> G3(6) | O6: =SUM(B6:K6) -> 28 | R6: TAC
A7: ATM_006 | B7: 1 | C7: 2 | D7: 4 | E7: 9 | F7: 12 | G7: 9 | H7: 5 | I7: 4 | J7: 0 | K7: 0 | L7: 0 | N7: =CONCATENATE("G",MATCH(MAX(B7:K7),B7:K7,0)-1,"(",MAX(B7:K7),")") -> G4(12) | O7: =SUM(B7:K7) -> 46 | Q7: Promedio | R7: =ROUNDUP(AVERAGE(O2:O151),0) & " ± " & ROUNDUP(_xlfn.STDEV.S(O2:O151),0) -> 28 ± 23
A8: ATM_007 | B8: 1 | C8: 1 | D8: 2 | E8: 4 | F8: 9 | G8: 14 | H8: 13 | I8: 2 | J8: 4 | K8: 1 | L8: 0 | N8: =CONCATENATE("G",MATCH(MAX(B8:K8),B8:K8,0)-1,"(",MAX(B8:K8),")") -> G5(14) | O8: =SUM(B8:K8) -> 51
A9: ATM_008 | B9: 1 | C9: 2 | D9: 4 | E9: 9 | F9: 17 | G9: 14 | H9: 6 | I9: 2 | J9: 1 | K9: 0 | L9: 0 | N9: =CONCATENATE("G",MATCH(MAX(B9:K9),B9:K9,0)-1,"(",MAX(B9:K9),")") -> G4(17) | O9: =SUM(B9:K9) -> 56
A10: ATM_009 | B10: 1 | C10: 2 | D10: 4 | E10: 5 | F10: 6 | G10: 3 | H10: 0 | I10: 0 | J10: 0 | K10: 0 | L10: 0 | N10: =CONCATENATE("G",MATCH(MAX(B10:K10),B10:K10,0)-1,"(",MAX(B10:K10),")") -> G4(6) | O10: =SUM(B10:K10) -> 21
A11: ATM_010 | B11: 1 | C11: 2 | D11: 4 | E11: 8 | F11: 6 | G11: 2 | H11: 0 | I11: 0 | J11: 0 | K11: 0 | L11: 0 | N11: =CONCATENATE("G",MATCH(MAX(B11:K11),B11:K11,0)-1,"(",MAX(B11:K11),")") -> G3(8) | O11: =SUM(B11:K11) -> 23
A12: ATM_011 | B12: 1 | C12: 2 | D12: 4 | E12: 9 | F12: 20 | G12: 24 | H12: 8 | I12: 6 | J12: 6 | K12: 2 | L12: 0 | N12: =CONCATENATE("G",MATCH(MAX(B12:K12),B12:K12,0)-1,"(",MAX(B12:K12),")") -> G5(24) | O12: =SUM(B12:K12) -> 82
A13: ATM_012 | B13: 1 | C13: 2 | D13: 4 | E13: 8 | F13: 4 | G13: 0 | H13: 0 | I13: 0 | J13: 0 | K13: 0 | L13: 0 | N13: =CONCATENATE("G",MATCH(MAX(B13:K13),B13:K13,0)-1,"(",MAX(B13:K13),")") -> G3(8) | O13: =SUM(B13:K13) -> 19
A14: ATM_013 | B14: 1 | C14: 2 | D14: 4 | E14: 9 | F14: 12 | G14: 8 | H14: 6 | I14: 8 | J14: 1 | K14: 2 | L14: 0 | N14: =CONCATENATE("G",MATCH(MAX(B14:K14),B14:K14,0)-1,"(",MAX(B14:K14),")") -> G4(12) | O14: =SUM(B14:K14) -> 53
A15: ATM_014 | B15: 1 | C15: 2 | D15: 4 | E15: 9 | F15: 12 | G15: 7 | H15: 2 | I15: 0 | J15: 0 | K15: 0 | L15: 0 | N15: =CONCATENATE("G",MATCH(MAX(B15:K15),B15:K15,0)-1,"(",MAX(B15:K15),")") -> G4(12) | O15: =SUM(B15:K15) -> 37
A16: ATM_015 | B16: 1 | C16: 2 | D16: 5 | E16: 0 | F16: 0 | G16: 0 | H16: 0 | I16: 0 | J16: 0 | K16: 0 | L16: 0 | N16: =CONCATENATE("G",MATCH(MAX(B16:K16),B16:K16,0)-1,"(",MAX(B16:K16),")") -> G2(5) | O16: =SUM(B16:K16) -> 8
A17: ATM_016 | B17: 1 | C17: 2 | D17: 4 | E17: 8 | F17: 8 | G17: 2 | H17: 2 | I17: 0 | J17: 0 | K17: 0 | L17: 0 | N17: =CONCATENATE("G",MATCH(MAX(B17:K17),B17:K17,0)-1,"(",MAX(B17:K17),")") -> G3(8) | O17: =SUM(B17:K17) -> 27
A18: ATM_017 | B18: 1 | C18: 2 | D18: 5 | E18: 7 | F18: 3 | G18: 0 | H18: 0 | I18: 0 | J18: 0 | K18: 0 | L18: 0 | N18: =CONCATENATE("G",MATCH(MAX(B18:K18),B18:K18,0)-1,"(",MAX(B18:K18),")") -> G3(7) | O18: =SUM(B18:K18) -> 18
A19: ATM_018 | B19: 1 | C19: 2 | D19: 4 | E19: 8 | F19: 8 | G19: 0 | H19: 0 | I19: 0 | J19: 0 | K19: 0 | L19: 0 | N19: =CONCATENATE("G",MATCH(MAX(B19:K19),B19:K19,0)-1,"(",MAX(B19:K19),")") -> G3(8) | O19: =SUM(B19:K19) -> 23
... A151: ATM_172 | B151: 1 | C151: 2 | D151: 4 | E151: 9 | F151: 13 | G151: 4 | H151: 4 | I151: 4 | J151: 2 | K151: 0 | L151: 0 | N151: =CONCATENATE("G",MATCH(MAX(B151:K151),B151:K151,0)-1,"(",MAX(B151:K151),")") -> G4(13) | O151: =SUM(B151:K151) -> 43

Sheet Clip
A1: Generaciones | B1: 0 | C1: 1 | D1: 2 | E1: 3 | F1: 4 | G1: 5 | H1: 6 | I1: 7 | J1: 8 | K1: 9 | L1: 10 | M1: 11 | O1: Peak | P1: TAC | S1: 0 | T1: 1 | U1: 2 | V1: 3 | W1: 4 | X1: 5 | Y1: 6 | Z1: 7 | AA1: 8 | AB1: 9 | AC1: 10 | AD1: 11
A2: ATM_001_airways | B2: 1 | C2: 1 | D2: 2 | E2: 4 | F2: 9 | G2: 8 | H2: 2 | I2: 2 | J2: 0 | K2: 0 | L2: 0 | M2: 0 | O2: =CONCATENATE("G",MATCH(MAX(B2:K2),B2:K2,0)-1,"(",MAX(B2:K2),")") -> G4(9) | P2: =SUM(B2:K2) -> 29 | R2: Promedio | S2: =ROUNDUP(AVERAGE(B2:B151), 0) -> 1 | T2: =ROUNDUP(AVERAGE(C2:C151), 0) -> 2 | U2: =ROUNDUP(AVERAGE(D2:D151), 0) -> 4 | V2: =ROUNDUP(AVERAGE(E2:E151), 0) -> 6 | W2: =ROUNDUP(AVERAGE(F2:F151), 0) -> 7 | X2: =ROUNDUP(AVERAGE(G2:G151), 0) -> 6 | Y2: =ROUNDUP(AVERAGE(H2:H151), 0) -> 3 | Z2: =ROUNDUP(AVERAGE(I2:I151), 0) -> 2 | ... AD2: =ROUNDUP(AVERAGE(M2:M151), 0) -> 0
A3: ATM_002_airways | B3: 1 | C3: 1 | D3: 2 | E3: 5 | F3: 8 | G3: 7 | H3: 6 | I3: 4 | J3: 2 | K3: 4 | L3: 0 | M3: 0 | O3: =CONCATENATE("G",MATCH(MAX(B3:K3),B3:K3,0)-1,"(",MAX(B3:K3),")") -> G4(8) | P3: =SUM(B3:K3) -> 40 | R3: Max | S3: =MAX(B2:B151) -> 1 | T3: =MAX(C2:C151) -> 3 | U3: =MAX(D2:D151) -> 5 | V3: =MAX(E2:E151) -> 12 | W3: =MAX(F2:F151) -> 20 | X3: =MAX(G2:G151) -> 35 | Y3: =MAX(H2:H151) -> 36 | Z3: =MAX(I2:I151) -> 26 | ... AD3: =MAX(M2:M151) -> 0
A4: ATM_003_airways | B4: 1 | C4: 1 | D4: 2 | E4: 4 | F4: 8 | G4: 4 | H4: 3 | I4: 0 | J4: 0 | K4: 0 | L4: 0 | M4: 0 | O4: =CONCATENATE("G",MATCH(MAX(B4:K4),B4:K4,0)-1,"(",MAX(B4:K4),")") -> G4(8) | P4: =SUM(B4:K4) -> 23 | R4: Moda | S4: =_xlfn.MODE.SNGL(B2:B151) -> 1 | T4: =_xlfn.MODE.SNGL(C2:C151) -> 2 | U4: =_xlfn.MODE.SNGL(D2:D151) -> 4 | V4: =_xlfn.MODE.SNGL(E2:E151) -> 9 | W4: =_xlfn.MODE.SNGL(F2:F151) -> 0 | X4: =_xlfn.MODE.SNGL(G2:G151) -> 0 | Y4: =_xlfn.MODE.SNGL(H2:H151) -> 0 | Z4: =_xlfn.MODE.SNGL(I2:I151) -> 0 | ... AD4: =_xlfn.MODE.SNGL(M2:M151) -> 0
A5: ATM_004_airways | B5: 1 | C5: 2 | D5: 4 | E5: 8 | F5: 17 | G5: 31 | H5: 17 | I5: 6 | J5: 4 | K5: 6 | L5: 0 | M5: 0 | O5: =CONCATENATE("G",MATCH(MAX(B5:K5),B5:K5,0)-1,"(",MAX(B5:K5),")") -> G5(31) | P5: =SUM(B5:K5) -> 96 | R5: Mediana | S5: =MEDIAN(B1:B151) -> 1 | T5: =MEDIAN(C1:C151) -> 2 | U5: =MEDIAN(D1:D151) -> 4 | V5: =MEDIAN(E1:E151) -> 6 | W5: =MEDIAN(F1:F151) -> 6 | X5: =MEDIAN(G1:G151) -> 4 | Y5: =MEDIAN(H1:H151) -> 2 | Z5: =MEDIAN(I1:I151) -> 0 | ... AD5: =MEDIAN(M1:M151) -> 0
A6: ATM_005_airways | B6: 1 | C6: 2 | D6: 4 | E6: 8 | F6: 6 | G6: 4 | H6: 3 | I6: 0 | J6: 0 | K6: 0 | L6: 0 | M6: 0 | O6: =CONCATENATE("G",MATCH(MAX(B6:K6),B6:K6,0)-1,"(",MAX(B6:K6),")") -> G3(8) | P6: =SUM(B6:K6) -> 28 | S6: TAC
A7: ATM_006_airways | B7: 1 | C7: 2 | D7: 4 | E7: 9 | F7: 14 | G7: 10 | H7: 5 | I7: 4 | J7: 1 | K7: 0 | L7: 0 | M7: 0 | O7: =CONCATENATE("G",MATCH(MAX(B7:K7),B7:K7,0)-1,"(",MAX(B7:K7),")") -> G4(14) | P7: =SUM(B7:K7) -> 50 | R7: Promedio | S7: =ROUNDUP(AVERAGE(P2:P151),0) & " ± " & ROUNDUP(_xlfn.STDEV.S(P2:P151),0) -> 29 ± 22
A8: ATM_007_airways | B8: 1 | C8: 2 | D8: 4 | E8: 10 | F8: 14 | G8: 13 | H8: 4 | I8: 1 | J8: 0 | K8: 0 | L8: 0 | M8: 0 | O8: =CONCATENATE("G",MATCH(MAX(B8:K8),B8:K8,0)-1,"(",MAX(B8:K8),")") -> G4(14) | P8: =SUM(B8:K8) -> 49
A9: ATM_008_airways | B9: 1 | C9: 1 | D9: 2 | E9: 4 | F9: 9 | G9: 17 | H9: 14 | I9: 6 | J9: 2 | K9: 1 | L9: 0 | M9: 0 | O9: =CONCATENATE("G",MATCH(MAX(B9:K9),B9:K9,0)-1,"(",MAX(B9:K9),")") -> G5(17) | P9: =SUM(B9:K9) -> 57
A10: ATM_009_airways | B10: 1 | C10: 2 | D10: 4 | E10: 7 | F10: 6 | G10: 0 | H10: 0 | I10: 0 | J10: 0 | K10: 0 | L10: 0 | M10: 0 | O10: =CONCATENATE("G",MATCH(MAX(B10:K10),B10:K10,0)-1,"(",MAX(B10:K10),")") -> G3(7) | P10: =SUM(B10:K10) -> 20
A11: ATM_010_airways | B11: 1 | C11: 2 | D11: 4 | E11: 6 | F11: 6 | G11: 2 | H11: 0 | I11: 0 | J11: 0 | K11: 0 | L11: 0 | M11: 0 | O11: =CONCATENATE("G",MATCH(MAX(B11:K11),B11:K11,0)-1,"(",MAX(B11:K11),")") -> G3(6) | P11: =SUM(B11:K11) -> 21
A12: ATM_011_airways | B12: 1 | C12: 2 | D12: 4 | E12: 9 | F12: 18 | G12: 27 | H12: 10 | I12: 6 | J12: 6 | K12: 2 | L12: 0 | M12: 0 | O12: =CONCATENATE("G",MATCH(MAX(B12:K12),B12:K12,0)-1,"(",MAX(B12:K12),")") -> G5(27) | P12: =SUM(B12:K12) -> 85
A13: ATM_012_airways | B13: 1 | C13: 2 | D13: 4 | E13: 8 | F13: 5 | G13: 1 | H13: 0 | I13: 0 | J13: 0 | K13: 0 | L13: 0 | M13: 0 | O13: =CONCATENATE("G",MATCH(MAX(B13:K13),B13:K13,0)-1,"(",MAX(B13:K13),")") -> G3(8) | P13: =SUM(B13:K13) -> 21
A14: ATM_013_airways | B14: 1 | C14: 2 | D14: 4 | E14: 9 | F14: 13 | G14: 9 | H14: 6 | I14: 2 | J14: 0 | K14: 0 | L14: 0 | M14: 0 | O14: =CONCATENATE("G",MATCH(MAX(B14:K14),B14:K14,0)-1,"(",MAX(B14:K14),")") -> G4(13) | P14: =SUM(B14:K14) -> 46
A15: ATM_014_airways | B15: 1 | C15: 2 | D15: 4 | E15: 8 | F15: 15 | G15: 6 | H15: 2 | I15: 0 | J15: 0 | K15: 0 | L15: 0 | M15: 0 | O15: =CONCATENATE("G",MATCH(MAX(B15:K15),B15:K15,0)-1,"(",MAX(B15:K15),")") -> G4(15) | P15: =SUM(B15:K15) -> 38
A16: ATM_015_airways | B16: 0 | C16: 0 | D16: 0 | E16: 0 | F16: 0 | G16: 0 | H16: 0 | I16: 0 | J16: 0 | K16: 0 | L16: 0 | M16: 0 | O16: =CONCATENATE("G",MATCH(MAX(B16:K16),B16:K16,0)-1,"(",MAX(B16:K16),")") -> G0(0) | P16: =SUM(B16:K16) -> 0
A17: ATM_016_airways | B17: 1 | C17: 2 | D17: 4 | E17: 10 | F17: 8 | G17: 4 | H17: 2 | I17: 0 | J17: 0 | K17: 0 | L17: 0 | M17: 0 | O17: =CONCATENATE("G",MATCH(MAX(B17:K17),B17:K17,0)-1,"(",MAX(B17:K17),")") -> G3(10) | P17: =SUM(B17:K17) -> 31
A18: ATM_017_airways | B18: 1 | C18: 2 | D18: 4 | E18: 9 | F18: 4 | G18: 0 | H18: 0 | I18: 0 | J18: 0 | K18: 0 | L18: 0 | M18: 0 | O18: =CONCATENATE("G",MATCH(MAX(B18:K18),B18:K18,0)-1,"(",MAX(B18:K18),")") -> G3(9) | P18: =SUM(B18:K18) -> 20
A19: ATM_018_airways | B19: 1 | C19: 2 | D19: 4 | E19: 8 | F19: 8 | G19: 0 | H19: 0 | I19: 0 | J19: 0 | K19: 0 | L19: 0 | M19: 0 | O19: =CONCATENATE("G",MATCH(MAX(B19:K19),B19:K19,0)-1,"(",MAX(B19:K19),")") -> G3(8) | P19: =SUM(B19:K19) -> 23
... A151: ATM_172_airways | B151: 1 | C151: 2 | D151: 4 | E151: 9 | F151: 10 | G151: 6 | H151: 4 | I151: 4 | J151: 2 | K151: 0 | L151: 0 | M151: 0 | O151: =CONCATENATE("G",MATCH(MAX(B151:K151),B151:K151,0)-1,"(",MAX(B151:K151),")") -> G4(10) | P151: =SUM(B151:K151) -> 42

Sheet Smo
A1: Generaciones | B1: 0 | C1: 1 | D1: 2 | E1: 3 | F1: 4 | G1: 5 | H1: 6 | I1: 7 | J1: 8 | K1: 9 | L1: 10 | M1: 11 | O1: Peak | P1: TAC | S1: 0 | T1: 1 | U1: 2 | V1: 3 | W1: 4 | X1: 5 | Y1: 6 | Z1: 7 | AA1: 8 | AB1: 9 | AC1: 10 | AD1: 11
A2: ATM_001_airways | B2: 1 | C2: 2 | D2: 4 | E2: 7 | F2: 8 | G2: 2 | H2: 0 | I2: 0 | J2: 0 | K2: 0 | L2: 0 | M2: 0 | O2: =CONCATENATE("G",MATCH(MAX(B2:K2),B2:K2,0)-1,"(",MAX(B2:K2),")") -> G4(8) | P2: =SUM(B2:K2) -> 24 | R2: Promedio | S2: =ROUNDUP(AVERAGE(B2:B151), 0) -> 1 | T2: =ROUNDUP(AVERAGE(C2:C151), 0) -> 2 | U2: =ROUNDUP(AVERAGE(D2:D151), 0) -> 4 | V2: =ROUNDUP(AVERAGE(E2:E151), 0) -> 5 | W2: =ROUNDUP(AVERAGE(F2:F151), 0) -> 4 | X2: =ROUNDUP(AVERAGE(G2:G151), 0) -> 2 | Y2: =ROUNDUP(AVERAGE(H2:H151), 0) -> 1 | Z2: =ROUNDUP(AVERAGE(I2:I151), 0) -> 1 | ... AD2: =ROUNDUP(AVERAGE(M2:M151), 0) -> 0
A3: ATM_002_airways | B3: 1 | C3: 1 | D3: 1 | E3: 2 | F3: 2 | G3: 4 | H3: 2 | I3: 0 | J3: 0 | K3: 0 | L3: 0 | M3: 0 | O3: =CONCATENATE("G",MATCH(MAX(B3:K3),B3:K3,0)-1,"(",MAX(B3:K3),")") -> G5(4) | P3: =SUM(B3:K3) -> 13 | R3: Max | S3: =MAX(B2:B151) -> 1 | T3: =MAX(C2:C151) -> 4 | U3: =MAX(D2:D151) -> 7 | V3: =MAX(E2:E151) -> 10 | W3: =MAX(F2:F151) -> 18 | X3: =MAX(G2:G151) -> 20 | Y3: =MAX(H2:H151) -> 8 | Z3: =MAX(I2:I151) -> 6 | ... AD3: =MAX(M2:M151) -> 0
A4: ATM_003_airways | B4: 1 | C4: 1 | D4: 2 | E4: 4 | F4: 6 | G4: 3 | H4: 0 | I4: 0 | J4: 0 | K4: 0 | L4: 0 | M4: 0 | O4: =CONCATENATE("G",MATCH(MAX(B4:K4),B4:K4,0)-1,"(",MAX(B4:K4),")") -> G4(6) | P4: =SUM(B4:K4) -> 17 | R4: Moda | S4: =_xlfn.MODE.SNGL(B2:B151) -> 1 | T4: =_xlfn.MODE.SNGL(C2:C151) -> 2 | U4: =_xlfn.MODE.SNGL(D2:D151) -> 4 | V4: =_xlfn.MODE.SNGL(E2:E151) -> 2 | W4: =_xlfn.MODE.SNGL(F2:F151) -> 0 | X4: =_xlfn.MODE.SNGL(G2:G151) -> 0 | Y4: =_xlfn.MODE.SNGL(H2:H151) -> 0 | Z4: =_xlfn.MODE.SNGL(I2:I151) -> 0 | ... AD4: =_xlfn.MODE.SNGL(M2:M151) -> 0
A5: ATM_004_airways | B5: 1 | C5: 2 | D5: 4 | E5: 8 | F5: 14 | G5: 9 | H5: 0 | I5: 0 | J5: 0 | K5: 0 | L5: 0 | M5: 0 | O5: =CONCATENATE("G",MATCH(MAX(B5:K5),B5:K5,0)-1,"(",MAX(B5:K5),")") -> G4(14) | P5: =SUM(B5:K5) -> 38 | R5: Mediana | S5: =MEDIAN(B1:B151) -> 1 | T5: =MEDIAN(C1:C151) -> 2 | U5: =MEDIAN(D1:D151) -> 4 | V5: =MEDIAN(E1:E151) -> 5 | W5: =MEDIAN(F1:F151) -> 3 | X5: =MEDIAN(G1:G151) -> 0 | Y5: =MEDIAN(H1:H151) -> 0 | Z5: =MEDIAN(I1:I151) -> 0 | ... AD5: =MEDIAN(M1:M151) -> 0
A6: ATM_005_airways | B6: 1 | C6: 2 | D6: 3 | E6: 4 | F6: 2 | G6: 0 | H6: 0 | I6: 0 | J6: 0 | K6: 0 | L6: 0 | M6: 0 | O6: =CONCATENATE("G",MATCH(MAX(B6:K6),B6:K6,0)-1,"(",MAX(B6:K6),")") -> G3(4) | P6: =SUM(B6:K6) -> 12 | S6: TAC
A7: ATM_006_airways | B7: 1 | C7: 2 | D7: 4 | E7: 8 | F7: 5 | G7: 4 | H7: 2 | I7: 0 | J7: 0 | K7: 0 | L7: 0 | M7: 0 | O7: =CONCATENATE("G",MATCH(MAX(B7:K7),B7:K7,0)-1,"(",MAX(B7:K7),")") -> G3(8) | P7: =SUM(B7:K7) -> 26 | R7: Promedio | S7: =ROUNDUP(AVERAGE(P2:P151),0) & " ± " & ROUNDUP(_xlfn.STDEV.S(P2:P151),0) -> 17 ± 12
A8: ATM_007_airways | B8: 1 | C8: 2 | D8: 4 | E8: 9 | F8: 12 | G8: 2 | H8: 2 | I8: 0 | J8: 0 | K8: 0 | L8: 0 | M8: 0 | O8: =CONCATENATE("G",MATCH(MAX(B8:K8),B8:K8,0)-1,"(",MAX(B8:K8),")") -> G4(12) | P8: =SUM(B8:K8) -> 32
A9: ATM_008_airways | B9: 1 | C9: 2 | D9: 4 | E9: 6 | F9: 8 | G9: 0 | H9: 0 | I9: 0 | J9: 0 | K9: 0 | L9: 0 | M9: 0 | O9: =CONCATENATE("G",MATCH(MAX(B9:K9),B9:K9,0)-1,"(",MAX(B9:K9),")") -> G4(8) | P9: =SUM(B9:K9) -> 21
A10: ATM_009_airways | B10: 1 | C10: 2 | D10: 4 | E10: 5 | F10: 0 | G10: 0 | H10: 0 | I10: 0 | J10: 0 | K10: 0 | L10: 0 | M10: 0 | O10: =CONCATENATE("G",MATCH(MAX(B10:K10),B10:K10,0)-1,"(",MAX(B10:K10),")") -> G3(5) | P10: =SUM(B10:K10) -> 12
A11: ATM_010_airways | B11: 1 | C11: 2 | D11: 4 | E11: 7 | F11: 2 | G11: 0 | H11: 0 | I11: 0 | J11: 0 | K11: 0 | L11: 0 | M11: 0 | O11: =CONCATENATE("G",MATCH(MAX(B11:K11),B11:K11,0)-1,"(",MAX(B11:K11),")") -> G3(7) | P11: =SUM(B11:K11) -> 16
A12: ATM_011_airways | B12: 1 | C12: 2 | D12: 4 | E12: 8 | F12: 12 | G12: 10 | H12: 6 | I12: 2 | J12: 2 | K12: 2 | L12: 4 | M12: 0 | O12: =CONCATENATE("G",MATCH(MAX(B12:K12),B12:K12,0)-1,"(",MAX(B12:K12),")") -> G4(12) | P12: =SUM(B12:K12) -> 49
A13: ATM_012_airways | B13: 1 | C13: 1 | D13: 2 | E13: 4 | F13: 5 | G13: 2 | H13: 0 | I13: 0 | J13: 0 | K13: 0 | L13: 0 | M13: 0 | O13: =CONCATENATE("G",MATCH(MAX(B13:K13),B13:K13,0)-1,"(",MAX(B13:K13),")") -> G4(5) | P13: =SUM(B13:K13) -> 15
A14: ATM_013_airways | B14: 1 | C14: 2 | D14: 4 | E14: 9 | F14: 4 | G14: 2 | H14: 1 | I14: 0 | J14: 0 | K14: 0 | L14: 0 | M14: 0 | O14: =CONCATENATE("G",MATCH(MAX(B14:K14),B14:K14,0)-1,"(",MAX(B14:K14),")") -> G3(9) | P14: =SUM(B14:K14) -> 23
A15: ATM_014_airways | B15: 1 | C15: 1 | D15: 2 | E15: 4 | F15: 6 | G15: 4 | H15: 0 | I15: 0 | J15: 0 | K15: 0 | L15: 0 | M15: 0 | O15: =CONCATENATE("G",MATCH(MAX(B15:K15),B15:K15,0)-1,"(",MAX(B15:K15),")") -> G4(6) | P15: =SUM(B15:K15) -> 18
A16: ATM_015_airways | B16: 0 | C16: 0 | D16: 0 | E16: 0 | F16: 0 | G16: 0 | H16: 0 | I16: 0 | J16: 0 | K16: 0 | L16: 0 | M16: 0 | O16: =CONCATENATE("G",MATCH(MAX(B16:K16),B16:K16,0)-1,"(",MAX(B16:K16),")") -> G0(0) | P16: =SUM(B16:K16) -> 0
A17: ATM_016_airways | B17: 1 | C17: 2 | D17: 4 | E17: 5 | F17: 3 | G17: 0 | H17: 0 | I17: 0 | J17: 0 | K17: 0 | L17: 0 | M17: 0 | O17: =CONCATENATE("G",MATCH(MAX(B17:K17),B17:K17,0)-1,"(",MAX(B17:K17),")") -> G3(5) | P17: =SUM(B17:K17) -> 15
A18: ATM_017_airways | B18: 1 | C18: 2 | D18: 4 | E18: 2 | F18: 0 | G18: 0 | H18: 0 | I18: 0 | J18: 0 | K18: 0 | L18: 0 | M18: 0 | O18: =CONCATENATE("G",MATCH(MAX(B18:K18),B18:K18,0)-1,"(",MAX(B18:K18),")") -> G2(4) | P18: =SUM(B18:K18) -> 9
A19: ATM_018_airways | B19: 1 | C19: 2 | D19: 4 | E19: 8 | F19: 4 | G19: 0 | H19: 0 | I19: 0 | J19: 0 | K19: 0 | L19: 0 | M19: 0 | O19: =CONCATENATE("G",MATCH(MAX(B19:K19),B19:K19,0)-1,"(",MAX(B19:K19),")") -> G3(8) | P19: =SUM(B19:K19) -> 19
... A151: ATM_172_airways | B151: 1 | C151: 2 | D151: 4 | E151: 6 | F151: 4 | G151: 0 | H151: 0 | I151: 0 | J151: 0 | K151: 0 | L151: 0 | M151: 0 | O151: =CONCATENATE("G",MATCH(MAX(B151:K151),B151:K151,0)-1,"(",MAX(B151:K151),")") -> G3(6) | P151: =SUM(B151:K151) -> 17

Sheet Norm
A1: Generaciones | B1: 0 | C1: 1 | D1: 2 | E1: 3 | F1: 4 | G1: 5 | H1: 6 | I1: 7 | J1: 8 | K1: 9 | L1: 10 | M1: 11 | O1: Peak | P1: TAC | S1: 0 | T1: 1 | U1: 2 | V1: 3 | W1: 4 | X1: 5 | Y1: 6 | Z1: 7 | AA1: 8 | AB1: 9 | AC1: 10 | AD1: 11
A2: ATM_001_airways | B2: 1 | C2: 2 | D2: 4 | E2: 7 | F2: 8 | G2: 2 | H2: 2 | I2: 0 | J2: 0 | K2: 0 | L2: 0 | M2: 0 | O2: =CONCATENATE("G",MATCH(MAX(B2:K2),B2:K2,0)-1,"(",MAX(B2:K2),")") -> G4(8) | P2: =SUM(B2:K2) -> 26 | R2: Promedio | S2: =ROUNDUP(AVERAGE(B2:B151), 0) -> 1 | T2: =ROUNDUP(AVERAGE(C2:C151), 0) -> 2 | U2: =ROUNDUP(AVERAGE(D2:D151), 0) -> 4 | V2: =ROUNDUP(AVERAGE(E2:E151), 0) -> 6 | W2: =ROUNDUP(AVERAGE(F2:F151), 0) -> 7 | X2: =ROUNDUP(AVERAGE(G2:G151), 0) -> 6 | Y2: =ROUNDUP(AVERAGE(H2:H151), 0) -> 3 | Z2: =ROUNDUP(AVERAGE(I2:I151), 0) -> 2 | ... AD2: =ROUNDUP(AVERAGE(M2:M151), 0) -> 1
A3: ATM_002_airways | B3: 1 | C3: 2 | D3: 2 | E3: 3 | F3: 5 | G3: 7 | H3: 7 | I3: 3 | J3: 2 | K3: 4 | L3: 0 | M3: 0 | O3: =CONCATENATE("G",MATCH(MAX(B3:K3),B3:K3,0)-1,"(",MAX(B3:K3),")") -> G5(7) | P3: =SUM(B3:K3) -> 36 | R3: Max | S3: =MAX(B2:B151) -> 1 | T3: =MAX(C2:C151) -> 4 | U3: =MAX(D2:D151) -> 5 | V3: =MAX(E2:E151) -> 10 | W3: =MAX(F2:F151) -> 24 | X3: =MAX(G2:G151) -> 36 | Y3: =MAX(H2:H151) -> 28 | Z3: =MAX(I2:I151) -> 13 | ... AD3: =MAX(M2:M151) -> 2
A4: ATM_003_airways | B4: 1 | C4: 1 | D4: 2 | E4: 4 | F4: 8 | G4: 5 | H4: 3 | I4: 0 | J4: 0 | K4: 0 | L4: 0 | M4: 0 | O4: =CONCATENATE("G",MATCH(MAX(B4:K4),B4:K4,0)-1,"(",MAX(B4:K4),")") -> G4(8) | P4: =SUM(B4:K4) -> 24 | R4: Moda | S4: =_xlfn.MODE.SNGL(B2:B151) -> 1 | T4: =_xlfn.MODE.SNGL(C2:C151) -> 2 | U4: =_xlfn.MODE.SNGL(D2:D151) -> 4 | V4: =_xlfn.MODE.SNGL(E2:E151) -> 9 | W4: =_xlfn.MODE.SNGL(F2:F151) -> 0 | X4: =_xlfn.MODE.SNGL(G2:G151) -> 0 | Y4: =_xlfn.MODE.SNGL(H2:H151) -> 0 | Z4: =_xlfn.MODE.SNGL(I2:I151) -> 0 | ... AD4: =_xlfn.MODE.SNGL(M2:M151) -> 0
A5: ATM_004_airways | B5: 1 | C5: 2 | D5: 4 | E5: 8 | F5: 18 | G5: 32 | H5: 20 | I5: 8 | J5: 7 | K5: 6 | L5: 0 | M5: 0 | O5: =CONCATENATE("G",MATCH(MAX(B5:K5),B5:K5,0)-1,"(",MAX(B5:K5),")") -> G5(32) | P5: =SUM(B5:K5) -> 106 | R5: Mediana | S5: =MEDIAN(B1:B151) -> 1 | T5: =MEDIAN(C1:C151) -> 2 | U5: =MEDIAN(D1:D151) -> 4 | V5: =MEDIAN(E1:E151) -> 6 | W5: =MEDIAN(F1:F151) -> 7 | X5: =MEDIAN(G1:G151) -> 4 | Y5: =MEDIAN(H1:H151) -> 2 | Z5: =MEDIAN(I1:I151) -> 0 | ... AD5: =MEDIAN(M1:M151) -> 0
A6: ATM_005_airways | B6: 1 | C6: 2 | D6: 4 | E6: 8 | F6: 6 | G6: 2 | H6: 3 | I6: 0 | J6: 0 | K6: 0 | L6: 0 | M6: 0 | O6: =CONCATENATE("G",MATCH(MAX(B6:K6),B6:K6,0)-1,"(",MAX(B6:K6),")") -> G3(8) | P6: =SUM(B6:K6) -> 26 | S6: TAC
A7: ATM_006_airways | B7: 1 | C7: 2 | D7: 3 | E7: 7 | F7: 12 | G7: 12 | H7: 6 | I7: 4 | J7: 4 | K7: 0 | L7: 0 | M7: 0 | O7: =CONCATENATE("G",MATCH(MAX(B7:K7),B7:K7,0)-1,"(",MAX(B7:K7),")") -> G4(12) | P7: =SUM(B7:K7) -> 51 | R7: Promedio | S7: =ROUNDUP(AVERAGE(P2:P151),0) & " ± " & ROUNDUP(_xlfn.STDEV.S(P2:P151),0) -> 29 ± 22
A8: ATM_007_airways | B8: 1 | C8: 2 | D8: 3 | E8: 8 | F8: 13 | G8: 12 | H8: 13 | I8: 6 | J8: 2 | K8: 0 | L8: 0 | M8: 0 | O8: =CONCATENATE("G",MATCH(MAX(B8:K8),B8:K8,0)-1,"(",MAX(B8:K8),")") -> G4(13) | P8: =SUM(B8:K8) -> 60
A9: ATM_008_airways | B9: 1 | C9: 2 | D9: 3 | E9: 6 | F9: 12 | G9: 16 | H9: 9 | I9: 2 | J9: 0 | K9: 0 | L9: 0 | M9: 0 | O9: =CONCATENATE("G",MATCH(MAX(B9:K9),B9:K9,0)-1,"(",MAX(B9:K9),")") -> G5(16) | P9: =SUM(B9:K9) -> 51
A10: ATM_009_airways | B10: 1 | C10: 2 | D10: 3 | E10: 6 | F10: 4 | G10: 4 | H10: 0 | I10: 0 | J10: 0 | K10: 0 | L10: 0 | M10: 0 | O10: =CONCATENATE("G",MATCH(MAX(B10:K10),B10:K10,0)-1,"(",MAX(B10:K10),")") -> G3(6) | P10: =SUM(B10:K10) -> 20
A11: ATM_010_airways | B11: 1 | C11: 2 | D11: 4 | E11: 8 | F11: 7 | G11: 3 | H11: 0 | I11: 0 | J11: 0 | K11: 0 | L11: 0 | M11: 0 | O11: =CONCATENATE("G",MATCH(MAX(B11:K11),B11:K11,0)-1,"(",MAX(B11:K11),")") -> G3(8) | P11: =SUM(B11:K11) -> 25
A12: ATM_011_airways | B12: 1 | C12: 2 | D12: 4 | E12: 9 | F12: 20 | G12: 28 | H12: 7 | I12: 6 | J12: 4 | K12: 2 | L12: 0 | M12: 0 | O12: =CONCATENATE("G",MATCH(MAX(B12:K12),B12:K12,0)-1,"(",MAX(B12:K12),")") -> G5(28) | P12: =SUM(B12:K12) -> 83
A13: ATM_012_airways | B13: 1 | C13: 2 | D13: 4 | E13: 9 | F13: 7 | G13: 2 | H13: 0 | I13: 0 | J13: 0 | K13: 0 | L13: 0 | M13: 0 | O13: =CONCATENATE("G",MATCH(MAX(B13:K13),B13:K13,0)-1,"(",MAX(B13:K13),")") -> G3(9) | P13: =SUM(B13:K13) -> 25
A14: ATM_013_airways | B14: 1 | C14: 2 | D14: 4 | E14: 9 | F14: 11 | G14: 8 | H14: 5 | I14: 6 | J14: 2 | K14: 0 | L14: 0 | M14: 0 | O14: =CONCATENATE("G",MATCH(MAX(B14:K14),B14:K14,0)-1,"(",MAX(B14:K14),")") -> G4(11) | P14: =SUM(B14:K14) -> 48
A15: ATM_014_airways | B15: 1 | C15: 2 | D15: 4 | E15: 9 | F15: 14 | G15: 6 | H15: 0 | I15: 0 | J15: 0 | K15: 0 | L15: 0 | M15: 0 | O15: =CONCATENATE("G",MATCH(MAX(B15:K15),B15:K15,0)-1,"(",MAX(B15:K15),")") -> G4(14) | P15: =SUM(B15:K15) -> 36
A16: ATM_015_airways | B16: 0 | C16: 0 | D16: 0 | E16: 0 | F16: 0 | G16: 0 | H16: 0 | I16: 0 | J16: 0 | K16: 0 | L16: 0 | M16: 0 | O16: =CONCATENATE("G",MATCH(MAX(B16:K16),B16:K16,0)-1,"(",MAX(B16:K16),")") -> G0(0) | P16: =SUM(B16:K16) -> 0
A17: ATM_016_airways | B17: 1 | C17: 2 | D17: 4 | E17: 6 | F17: 6 | G17: 4 | H17: 4 | I17: 2 | J17: 0 | K17: 0 | L17: 0 | M17: 0 | O17: =CONCATENATE("G",MATCH(MAX(B17:K17),B17:K17,0)-1,"(",MAX(B17:K17),")") -> G3(6) | P17: =SUM(B17:K17) -> 29
A18: ATM_017_airways | B18: 1 | C18: 2 | D18: 4 | E18: 7 | F18: 4 | G18: 2 | H18: 0 | I18: 0 | J18: 0 | K18: 0 | L18: 0 | M18: 0 | O18: =CONCATENATE("G",MATCH(MAX(B18:K18),B18:K18,0)-1,"(",MAX(B18:K18),")") -> G3(7) | P18: =SUM(B18:K18) -> 20
A19: ATM_018_airways | B19: 1 | C19: 2 | D19: 4 | E19: 8 | F19: 8 | G19: 2 | H19: 0 | I19: 0 | J19: 0 | K19: 0 | L19: 0 | M19: 0 | O19: =CONCATENATE("G",MATCH(MAX(B19:K19),B19:K19,0)-1,"(",MAX(B19:K19),")") -> G3(8) | P19: =SUM(B19:K19) -> 25
... A151: ATM_172_airways | B151: 1 | C151: 2 | D151: 4 | E151: 9 | F151: 12 | G151: 7 | H151: 4 | I151: 4 | J151: 0 | K151: 0 | L151: 0 | M151: 0 | O151: =CONCATENATE("G",MATCH(MAX(B151:K151),B151:K151,0)-1,"(",MAX(B151:K151),")") -> G4(12) | P151: =SUM(B151:K151) -> 43

Sheet Pad
A1: Generaciones | B1: 0 | C1: 1 | D1: 2 | E1: 3 | F1: 4 | G1: 5 | H1: 6 | I1: 7 | J1: 8 | K1: 9 | L1: 10 | M1: 11 | O1: Peak | P1: TAC | S1: 0 | T1: 1 | U1: 2 | V1: 3 | W1: 4 | X1: 5 | Y1: 6 | Z1: 7 | AA1: 8 | AB1: 9 | AC1: 10 | AD1: 11
A2: ATM_001_airways | B2: 1 | C2: 1 | D2: 2 | E2: 4 | F2: 9 | G2: 8 | H2: 2 | I2: 2 | J2: 4 | K2: 0 | L2: 0 | M2: 0 | O2: =CONCATENATE("G",MATCH(MAX(B2:K2),B2:K2,0)-1,"(",MAX(B2:K2),")") -> G4(9) | P2: =SUM(B2:K2) -> 33 | R2: Promedio | S2: =ROUNDUP(AVERAGE(B2:B151), 0) -> 1 | T2: =ROUNDUP(AVERAGE(C2:C151), 0) -> 2 | U2: =ROUNDUP(AVERAGE(D2:D151), 0) -> 4 | V2: =ROUNDUP(AVERAGE(E2:E151), 0) -> 7 | W2: =ROUNDUP(AVERAGE(F2:F151), 0) -> 9 | X2: =ROUNDUP(AVERAGE(G2:G151), 0) -> 8 | Y2: =ROUNDUP(AVERAGE(H2:H151), 0) -> 5 | Z2: =ROUNDUP(AVERAGE(I2:I151), 0) -> 2 | ... AD2: =ROUNDUP(AVERAGE(M2:M151), 0) -> 1
A3: ATM_002_airways | B3: 1 | C3: 2 | D3: 3 | E3: 4 | F3: 9 | G3: 15 | H3: 7 | I3: 3 | J3: 0 | K3: 0 | L3: 0 | M3: 0 | O3: =CONCATENATE("G",MATCH(MAX(B3:K3),B3:K3,0)-1,"(",MAX(B3:K3),")") -> G5(15) | P3: =SUM(B3:K3) -> 44 | R3: Max | S3: =MAX(B2:B151) -> 1 | T3: =MAX(C2:C151) -> 3 | U3: =MAX(D2:D151) -> 5 | V3: =MAX(E2:E151) -> 12 | W3: =MAX(F2:F151) -> 23 | X3: =MAX(G2:G151) -> 36 | Y3: =MAX(H2:H151) -> 38 | Z3: =MAX(I2:I151) -> 16 | ... AD3: =MAX(M2:M151) -> 2
A4: ATM_003_airways | B4: 1 | C4: 2 | D4: 4 | E4: 8 | F4: 14 | G4: 8 | H4: 2 | I4: 0 | J4: 0 | K4: 0 | L4: 0 | M4: 0 | O4: =CONCATENATE("G",MATCH(MAX(B4:K4),B4:K4,0)-1,"(",MAX(B4:K4),")") -> G4(14) | P4: =SUM(B4:K4) -> 39 | R4: Moda | S4: =_xlfn.MODE.SNGL(B2:B151) -> 1 | T4: =_xlfn.MODE.SNGL(C2:C151) -> 2 | U4: =_xlfn.MODE.SNGL(D2:D151) -> 4 | V4: =_xlfn.MODE.SNGL(E2:E151) -> 9 | W4: =_xlfn.MODE.SNGL(F2:F151) -> 0 | X4: =_xlfn.MODE.SNGL(G2:G151) -> 0 | Y4: =_xlfn.MODE.SNGL(H2:H151) -> 0 | Z4: =_xlfn.MODE.SNGL(I2:I151) -> 0 | ... AD4: =_xlfn.MODE.SNGL(M2:M151) -> 0
A5: ATM_004_airways | B5: 1 | C5: 2 | D5: 4 | E5: 8 | F5: 17 | G5: 29 | H5: 20 | I5: 10 | J5: 8 | K5: 6 | L5: 0 | M5: 0 | O5: =CONCATENATE("G",MATCH(MAX(B5:K5),B5:K5,0)-1,"(",MAX(B5:K5),")") -> G5(29) | P5: =SUM(B5:K5) -> 105 | R5: Mediana | S5: =MEDIAN(B1:B151) -> 1 | T5: =MEDIAN(C1:C151) -> 2 | U5: =MEDIAN(D1:D151) -> 4 | V5: =MEDIAN(E1:E151) -> 8 | W5: =MEDIAN(F1:F151) -> 8 | X5: =MEDIAN(G1:G151) -> 6 | Y5: =MEDIAN(H1:H151) -> 2 | Z5: =MEDIAN(I1:I151) -> 0 | ... AD5: =MEDIAN(M1:M151) -> 0
A6: ATM_005_airways | B6: 1 | C6: 2 | D6: 4 | E6: 9 | F6: 14 | G6: 4 | H6: 3 | I6: 0 | J6: 0 | K6: 0 | L6: 0 | M6: 0 | O6: =CONCATENATE("G",MATCH(MAX(B6:K6),B6:K6,0)-1,"(",MAX(B6:K6),")") -> G4(14) | P6: =SUM(B6:K6) -> 37 | S6: TAC
A7: ATM_006_airways | B7: 1 | C7: 2 | D7: 3 | E7: 7 | F7: 13 | G7: 16 | H7: 11 | I7: 8 | J7: 3 | K7: 2 | L7: 0 | M7: 0 | O7: =CONCATENATE("G",MATCH(MAX(B7:K7),B7:K7,0)-1,"(",MAX(B7:K7),")") -> G5(16) | P7: =SUM(B7:K7) -> 66 | R7: Promedio | S7: =ROUNDUP(AVERAGE(P2:P151),0) & " ± " & ROUNDUP(_xlfn.STDEV.S(P2:P151),0) -> 37 ± 24
A8: ATM_007_airways | B8: 1 | C8: 2 | D8: 4 | E8: 9 | F8: 14 | G8: 13 | H8: 2 | I8: 2 | J8: 4 | K8: 0 | L8: 0 | M8: 0 | O8: =CONCATENATE("G",MATCH(MAX(B8:K8),B8:K8,0)-1,"(",MAX(B8:K8),")") -> G4(14) | P8: =SUM(B8:K8) -> 51
A9: ATM_008_airways | B9: 1 | C9: 2 | D9: 4 | E9: 9 | F9: 20 | G9: 16 | H9: 15 | I9: 4 | J9: 0 | K9: 0 | L9: 0 | M9: 0 | O9: =CONCATENATE("G",MATCH(MAX(B9:K9),B9:K9,0)-1,"(",MAX(B9:K9),")") -> G4(20) | P9: =SUM(B9:K9) -> 71
A10: ATM_009_airways | B10: 1 | C10: 2 | D10: 4 | E10: 7 | F10: 9 | G10: 0 | H10: 0 | I10: 0 | J10: 0 | K10: 0 | L10: 0 | M10: 0 | O10: =CONCATENATE("G",MATCH(MAX(B10:K10),B10:K10,0)-1,"(",MAX(B10:K10),")") -> G4(9) | P10: =SUM(B10:K10) -> 23
A11: ATM_010_airways | B11: 1 | C11: 1 | D11: 2 | E11: 4 | F11: 6 | G11: 6 | H11: 2 | I11: 0 | J11: 0 | K11: 0 | L11: 0 | M11: 0 | O11: =CONCATENATE("G",MATCH(MAX(B11:K11),B11:K11,0)-1,"(",MAX(B11:K11),")") -> G4(6) | P11: =SUM(B11:K11) -> 22
A12: ATM_011_airways | B12: 1 | C12: 2 | D12: 4 | E12: 9 | F12: 17 | G12: 28 | H12: 19 | I12: 6 | J12: 4 | K12: 2 | L12: 0 | M12: 0 | O12: =CONCATENATE("G",MATCH(MAX(B12:K12),B12:K12,0)-1,"(",MAX(B12:K12),")") -> G5(28) | P12: =SUM(B12:K12) -> 92
A13: ATM_012_airways | B13: 1 | C13: 1 | D13: 2 | E13: 4 | F13: 8 | G13: 8 | H13: 2 | I13: 0 | J13: 0 | K13: 0 | L13: 0 | M13: 0 | O13: =CONCATENATE("G",MATCH(MAX(B13:K13),B13:K13,0)-1,"(",MAX(B13:K13),")") -> G4(8) | P13: =SUM(B13:K13) -> 26
A14: ATM_013_airways | B14: 1 | C14: 1 | D14: 2 | E14: 4 | F14: 9 | G14: 11 | H14: 8 | I14: 4 | J14: 6 | K14: 1 | L14: 2 | M14: 0 | O14: =CONCATENATE("G",MATCH(MAX(B14:K14),B14:K14,0)-1,"(",MAX(B14:K14),")") -> G5(11) | P14: =SUM(B14:K14) -> 47
A15: ATM_014_airways | B15: 1 | C15: 2 | D15: 4 | E15: 8 | F15: 14 | G15: 18 | H15: 8 | I15: 4 | J15: 0 | K15: 0 | L15: 0 | M15: 0 | O15: =CONCATENATE("G",MATCH(MAX(B15:K15),B15:K15,0)-1,"(",MAX(B15:K15),")") -> G5(18) | P15: =SUM(B15:K15) -> 59
A16: ATM_015_airways | B16: 1 | C16: 2 | D16: 4 | E16: 8 | F16: 0 | G16: 0 | H16: 0 | I16: 0 | J16: 0 | K16: 0 | L16: 0 | M16: 0 | O16: =CONCATENATE("G",MATCH(MAX(B16:K16),B16:K16,0)-1,"(",MAX(B16:K16),")") -> G3(8) | P16: =SUM(B16:K16) -> 15
A17: ATM_016_airways | B17: 1 | C17: 2 | D17: 4 | E17: 9 | F17: 18 | G17: 13 | H17: 3 | I17: 2 | J17: 0 | K17: 0 | L17: 0 | M17: 0 | O17: =CONCATENATE("G",MATCH(MAX(B17:K17),B17:K17,0)-1,"(",MAX(B17:K17),")") -> G4(18) | P17: =SUM(B17:K17) -> 52
A18: ATM_017_airways | B18: 1 | C18: 3 | D18: 4 | E18: 10 | F18: 8 | G18: 3 | H18: 0 | I18: 0 | J18: 0 | K18: 0 | L18: 0 | M18: 0 | O18: =CONCATENATE("G",MATCH(MAX(B18:K18),B18:K18,0)-1,"(",MAX(B18:K18),")") -> G3(10) | P18: =SUM(B18:K18) -> 29
A19: ATM_018_airways | B19: 1 | C19: 2 | D19: 4 | E19: 9 | F19: 9 | G19: 4 | H19: 0 | I19: 0 | J19: 0 | K19: 0 | L19: 0 | M19: 0 | O19: =CONCATENATE("G",MATCH(MAX(B19:K19),B19:K19,0)-1,"(",MAX(B19:K19),")") -> G3(9) | P19: =SUM(B19:K19) -> 29
... A151: ATM_172_airways | B151: 1 | C151: 0 | D151: 0 | E151: 0 | F151: 0 | G151: 0 | H151: 0 | I151: 0 | J151: 0 | K151: 0 | L151: 0 | M151: 0 | O151: =CONCATENATE("G",MATCH(MAX(B151:K151),B151:K151,0)-1,"(",MAX(B151:K151),")") -> G0(1) | P151: =SUM(B151:K151) -> 1

Sheet Clip_Smo
A1: Generaciones | B1: 0 | C1: 1 | D1: 2 | E1: 3 | F1: 4 | G1: 5 | H1: 6 | I1: 7 | J1: 8 | K1: 9 | L1: 10 | M1: 11 | O1: Peak | P1: TAC | S1: 0 | T1: 1 | U1: 2 | V1: 3 | W1: 4 | X1: 5 | Y1: 6 | Z1: 7 | AA1: 8 | AB1: 9 | AC1: 10 | AD1: 11
A2: ATM_001_airways | B2: 1 | C2: 2 | D2: 5 | E2: 7 | F2: 7 | G2: 2 | H2: 0 | I2: 0 | J2: 0 | K2: 0 | L2: 0 | M2: 0 | O2: =CONCATENATE("G",MATCH(MAX(B2:K2),B2:K2,0)-1,"(",MAX(B2:K2),")") -> G3(7) | P2: =SUM(B2:K2) -> 24 | R2: Promedio | S2: =ROUNDUP(AVERAGE(B2:B151), 0) -> 1 | T2: =ROUNDUP(AVERAGE(C2:C151), 0) -> 2 | U2: =ROUNDUP(AVERAGE(D2:D151), 0) -> 3 | V2: =ROUNDUP(AVERAGE(E2:E151), 0) -> 5 | W2: =ROUNDUP(AVERAGE(F2:F151), 0) -> 4 | X2: =ROUNDUP(AVERAGE(G2:G151), 0) -> 2 | Y2: =ROUNDUP(AVERAGE(H2:H151), 0) -> 1 | Z2: =ROUNDUP(AVERAGE(I2:I151), 0) -> 1 | ... AD2: =ROUNDUP(AVERAGE(M2:M151), 0) -> 0
A3: ATM_002_airways | B3: 1 | C3: 2 | D3: 2 | E3: 3 | F3: 2 | G3: 0 | H3: 0 | I3: 0 | J3: 0 | K3: 0 | L3: 0 | M3: 0 | O3: =CONCATENATE("G",MATCH(MAX(B3:K3),B3:K3,0)-1,"(",MAX(B3:K3),")") -> G3(3) | P3: =SUM(B3:K3) -> 10 | R3: Max | S3: =MAX(B2:B151) -> 1 | T3: =MAX(C2:C151) -> 4 | U3: =MAX(D2:D151) -> 5 | V3: =MAX(E2:E151) -> 10 | W3: =MAX(F2:F151) -> 19 | X3: =MAX(G2:G151) -> 14 | Y3: =MAX(H2:H151) -> 8 | Z3: =MAX(I2:I151) -> 6 | ... AD3: =MAX(M2:M151) -> 0
A4: ATM_003_airways | B4: 1 | C4: 1 | D4: 2 | E4: 4 | F4: 6 | G4: 2 | H4: 0 | I4: 0 | J4: 0 | K4: 0 | L4: 0 | M4: 0 | O4: =CONCATENATE("G",MATCH(MAX(B4:K4),B4:K4,0)-1,"(",MAX(B4:K4),")") -> G4(6) | P4: =SUM(B4:K4) -> 16 | R4: Moda | S4: =_xlfn.MODE.SNGL(B2:B151) -> 1 | T4: =_xlfn.MODE.SNGL(C2:C151) -> 2 | U4: =_xlfn.MODE.SNGL(D2:D151) -> 4 | V4: =_xlfn.MODE.SNGL(E2:E151) -> 4 | W4: =_xlfn.MODE.SNGL(F2:F151) -> 0 | X4: =_xlfn.MODE.SNGL(G2:G151) -> 0 | Y4: =_xlfn.MODE.SNGL(H2:H151) -> 0 | Z4: =_xlfn.MODE.SNGL(I2:I151) -> 0 | ... AD4: =_xlfn.MODE.SNGL(M2:M151) -> 0
A5: ATM_004_airways | B5: 1 | C5: 2 | D5: 4 | E5: 8 | F5: 14 | G5: 8 | H5: 0 | I5: 0 | J5: 0 | K5: 0 | L5: 0 | M5: 0 | O5: =CONCATENATE("G",MATCH(MAX(B5:K5),B5:K5,0)-1,"(",MAX(B5:K5),")") -> G4(14) | P5: =SUM(B5:K5) -> 37 | R5: Mediana | S5: =MEDIAN(B1:B151) -> 1 | T5: =MEDIAN(C1:C151) -> 2 | U5: =MEDIAN(D1:D151) -> 4 | V5: =MEDIAN(E1:E151) -> 4 | W5: =MEDIAN(F1:F151) -> 3 | X5: =MEDIAN(G1:G151) -> 0 | Y5: =MEDIAN(H1:H151) -> 0 | Z5: =MEDIAN(I1:I151) -> 0 | ... AD5: =MEDIAN(M1:M151) -> 0
A6: ATM_005_airways | B6: 1 | C6: 2 | D6: 4 | E6: 1 | F6: 2 | G6: 0 | H6: 0 | I6: 0 | J6: 0 | K6: 0 | L6: 0 | M6: 0 | O6: =CONCATENATE("G",MATCH(MAX(B6:K6),B6:K6,0)-1,"(",MAX(B6:K6),")") -> G2(4) | P6: =SUM(B6:K6) -> 10 | S6: TAC
A7: ATM_006_airways | B7: 1 | C7: 2 | D7: 3 | E7: 6 | F7: 6 | G7: 5 | H7: 4 | I7: 0 | J7: 0 | K7: 0 | L7: 0 | M7: 0 | O7: =CONCATENATE("G",MATCH(MAX(B7:K7),B7:K7,0)-1,"(",MAX(B7:K7),")") -> G3(6) | P7: =SUM(B7:K7) -> 27 | R7: Promedio | S7: =ROUNDUP(AVERAGE(P2:P151),0) & " ± " & ROUNDUP(_xlfn.STDEV.S(P2:P151),0) -> 17 ± 11
A8: ATM_007_airways | B8: 1 | C8: 2 | D8: 4 | E8: 9 | F8: 12 | G8: 2 | H8: 2 | I8: 0 | J8: 0 | K8: 0 | L8: 0 | M8: 0 | O8: =CONCATENATE("G",MATCH(MAX(B8:K8),B8:K8,0)-1,"(",MAX(B8:K8),")") -> G4(12) | P8: =SUM(B8:K8) -> 32
A9: ATM_008_airways | B9: 1 | C9: 2 | D9: 4 | E9: 6 | F9: 7 | G9: 1 | H9: 0 | I9: 0 | J9: 0 | K9: 0 | L9: 0 | M9: 0 | O9: =CONCATENATE("G",MATCH(MAX(B9:K9),B9:K9,0)-1,"(",MAX(B9:K9),")") -> G4(7) | P9: =SUM(B9:K9) -> 21
A10: ATM_009_airways | B10: 1 | C10: 2 | D10: 4 | E10: 5 | F10: 0 | G10: 0 | H10: 0 | I10: 0 | J10: 0 | K10: 0 | L10: 0 | M10: 0 | O10: =CONCATENATE("G",MATCH(MAX(B10:K10),B10:K10,0)-1,"(",MAX(B10:K10),")") -> G3(5) | P10: =SUM(B10:K10) -> 12
A11: ATM_010_airways | B11: 1 | C11: 1 | D11: 1 | E11: 2 | F11: 4 | G11: 8 | H11: 0 | I11: 0 | J11: 0 | K11: 0 | L11: 0 | M11: 0 | O11: =CONCATENATE("G",MATCH(MAX(B11:K11),B11:K11,0)-1,"(",MAX(B11:K11),")") -> G5(8) | P11: =SUM(B11:K11) -> 17
A12: ATM_011_airways | B12: 1 | C12: 2 | D12: 4 | E12: 9 | F12: 14 | G12: 14 | H12: 2 | I12: 2 | J12: 4 | K12: 0 | L12: 0 | M12: 0 | O12: =CONCATENATE("G",MATCH(MAX(B12:K12),B12:K12,0)-1,"(",MAX(B12:K12),")") -> G4(14) | P12: =SUM(B12:K12) -> 52
A13: ATM_012_airways | B13: 1 | C13: 2 | D13: 4 | E13: 5 | F13: 3 | G13: 2 | H13: 0 | I13: 0 | J13: 0 | K13: 0 | L13: 0 | M13: 0 | O13: =CONCATENATE("G",MATCH(MAX(B13:K13),B13:K13,0)-1,"(",MAX(B13:K13),")") -> G3(5) | P13: =SUM(B13:K13) -> 17
A14: ATM_013_airways | B14: 1 | C14: 2 | D14: 4 | E14: 9 | F14: 4 | G14: 2 | H14: 1 | I14: 1 | J14: 0 | K14: 0 | L14: 0 | M14: 0 | O14: =CONCATENATE("G",MATCH(MAX(B14:K14),B14:K14,0)-1,"(",MAX(B14:K14),")") -> G3(9) | P14: =SUM(B14:K14) -> 24
A15: ATM_014_airways | B15: 1 | C15: 2 | D15: 4 | E15: 6 | F15: 7 | G15: 0 | H15: 0 | I15: 0 | J15: 0 | K15: 0 | L15: 0 | M15: 0 | O15: =CONCATENATE("G",MATCH(MAX(B15:K15),B15:K15,0)-1,"(",MAX(B15:K15),")") -> G4(7) | P15: =SUM(B15:K15) -> 20
A16: ATM_015_airways | B16: 0 | C16: 0 | D16: 0 | E16: 0 | F16: 0 | G16: 0 | H16: 0 | I16: 0 | J16: 0 | K16: 0 | L16: 0 | M16: 0 | O16: =CONCATENATE("G",MATCH(MAX(B16:K16),B16:K16,0)-1,"(",MAX(B16:K16),")") -> G0(0) | P16: =SUM(B16:K16) -> 0
A17: ATM_016_airways | B17: 1 | C17: 2 | D17: 4 | E17: 6 | F17: 2 | G17: 0 | H17: 0 | I17: 0 | J17: 0 | K17: 0 | L17: 0 | M17: 0 | O17: =CONCATENATE("G",MATCH(MAX(B17:K17),B17:K17,0)-1,"(",MAX(B17:K17),")") -> G3(6) | P17: =SUM(B17:K17) -> 15
A18: ATM_017_airways | B18: 1 | C18: 2 | D18: 4 | E18: 3 | F18: 0 | G18: 0 | H18: 0 | I18: 0 | J18: 0 | K18: 0 | L18: 0 | M18: 0 | O18: =CONCATENATE("G",MATCH(MAX(B18:K18),B18:K18,0)-1,"(",MAX(B18:K18),")") -> G2(4) | P18: =SUM(B18:K18) -> 10
A19: ATM_018_airways | B19: 1 | C19: 2 | D19: 4 | E19: 8 | F19: 8 | G19: 0 | H19: 0 | I19: 0 | J19: 0 | K19: 0 | L19: 0 | M19: 0 | O19: =CONCATENATE("G",MATCH(MAX(B19:K19),B19:K19,0)-1,"(",MAX(B19:K19),")") -> G3(8) | P19: =SUM(B19:K19) -> 23
... A151: ATM_172_airways | B151: 1 | C151: 2 | D151: 4 | E151: 6 | F151: 4 | G151: 0 | H151: 0 | I151: 0 | J151: 0 | K151: 0 | L151: 0 | M151: 0 | O151: =CONCATENATE("G",MATCH(MAX(B151:K151),B151:K151,0)-1,"(",MAX(B151:K151),")") -> G3(6) | P151: =SUM(B151:K151) -> 17

Sheet Clip_Norm
A1: Generaciones | B1: 0 | C1: 1 | D1: 2 | E1: 3 | F1: 4 | G1: 5 | H1: 6 | I1: 7 | J1: 8 | K1: 9 | L1: 10 | M1: 11 | O1: Peak | P1: TAC | S1: 0 | T1: 1 | U1: 2 | V1: 3 | W1: 4 | X1: 5 | Y1: 6 | Z1: 7 | AA1: 8 | AB1: 9 | AC1: 10 | AD1: 11
A2: ATM_001_airways | B2: 1 | C2: 2 | D2: 4 | E2: 9 | F2: 8 | G2: 2 | H2: 4 | I2: 0 | J2: 0 | K2: 0 | L2: 0 | M2: 0 | O2: =CONCATENATE("G",MATCH(MAX(B2:K2),B2:K2,0)-1,"(",MAX(B2:K2),")") -> G3(9) | P2: =SUM(B2:K2) -> 30 | R2: Promedio | S2: =ROUNDUP(AVERAGE(B2:B151), 0) -> 1 | T2: =ROUNDUP(AVERAGE(C2:C151), 0) -> 2 | U2: =ROUNDUP(AVERAGE(D2:D151), 0) -> 4 | V2: =ROUNDUP(AVERAGE(E2:E151), 0) -> 6 | W2: =ROUNDUP(AVERAGE(F2:F151), 0) -> 7 | X2: =ROUNDUP(AVERAGE(G2:G151), 0) -> 6 | Y2: =ROUNDUP(AVERAGE(H2:H151), 0) -> 4 | Z2: =ROUNDUP(AVERAGE(I2:I151), 0) -> 2 | ... AD2: =ROUNDUP(AVERAGE(M2:M151), 0) -> 0
A3: ATM_002_airways | B3: 1 | C3: 1 | D3: 2 | E3: 5 | F3: 5 | G3: 8 | H3: 3 | I3: 2 | J3: 4 | K3: 0 | L3: 0 | M3: 0 | O3: =CONCATENATE("G",MATCH(MAX(B3:K3),B3:K3,0)-1,"(",MAX(B3:K3),")") -> G5(8) | P3: =SUM(B3:K3) -> 31 | R3: Max | S3: =MAX(B2:B151) -> 2 | T3: =MAX(C2:C151) -> 3 | U3: =MAX(D2:D151) -> 5 | V3: =MAX(E2:E151) -> 11 | W3: =MAX(F2:F151) -> 21 | X3: =MAX(G2:G151) -> 35 | Y3: =MAX(H2:H151) -> 36 | Z3: =MAX(I2:I151) -> 17 | ... AD3: =MAX(M2:M151) -> 0
A4: ATM_003_airways | B4: 1 | C4: 2 | D4: 2 | E4: 4 | F4: 8 | G4: 8 | H4: 0 | I4: 0 | J4: 0 | K4: 0 | L4: 0 | M4: 0 | O4: =CONCATENATE("G",MATCH(MAX(B4:K4),B4:K4,0)-1,"(",MAX(B4:K4),")") -> G4(8) | P4: =SUM(B4:K4) -> 25 | R4: Moda | S4: =_xlfn.MODE.SNGL(B2:B151) -> 1 | T4: =_xlfn.MODE.SNGL(C2:C151) -> 2 | U4: =_xlfn.MODE.SNGL(D2:D151) -> 4 | V4: =_xlfn.MODE.SNGL(E2:E151) -> 4 | W4: =_xlfn.MODE.SNGL(F2:F151) -> 0 | X4: =_xlfn.MODE.SNGL(G2:G151) -> 0 | Y4: =_xlfn.MODE.SNGL(H2:H151) -> 0 | Z4: =_xlfn.MODE.SNGL(I2:I151) -> 0 | ... AD4: =_xlfn.MODE.SNGL(M2:M151) -> 0
A5: ATM_004_airways | B5: 1 | C5: 2 | D5: 4 | E5: 8 | F5: 16 | G5: 30 | H5: 23 | I5: 8 | J5: 9 | K5: 6 | L5: 0 | M5: 0 | O5: =CONCATENATE("G",MATCH(MAX(B5:K5),B5:K5,0)-1,"(",MAX(B5:K5),")") -> G5(30) | P5: =SUM(B5:K5) -> 107 | R5: Mediana | S5: =MEDIAN(B1:B151) -> 1 | T5: =MEDIAN(C1:C151) -> 2 | U5: =MEDIAN(D1:D151) -> 4 | V5: =MEDIAN(E1:E151) -> 6 | W5: =MEDIAN(F1:F151) -> 7 | X5: =MEDIAN(G1:G151) -> 4 | Y5: =MEDIAN(H1:H151) -> 1 | Z5: =MEDIAN(I1:I151) -> 0 | ... AD5: =MEDIAN(M1:M151) -> 0
A6: ATM_005_airways | B6: 1 | C6: 2 | D6: 4 | E6: 8 | F6: 6 | G6: 4 | H6: 3 | I6: 0 | J6: 0 | K6: 0 | L6: 0 | M6: 0 | O6: =CONCATENATE("G",MATCH(MAX(B6:K6),B6:K6,0)-1,"(",MAX(B6:K6),")") -> G3(8) | P6: =SUM(B6:K6) -> 28 | S6: TAC
A7: ATM_006_airways | B7: 1 | C7: 2 | D7: 4 | E7: 10 | F7: 11 | G7: 9 | H7: 7 | I7: 0 | J7: 0 | K7: 0 | L7: 0 | M7: 0 | O7: =CONCATENATE("G",MATCH(MAX(B7:K7),B7:K7,0)-1,"(",MAX(B7:K7),")") -> G4(11) | P7: =SUM(B7:K7) -> 44 | R7: Promedio | S7: =ROUNDUP(AVERAGE(P2:P151),0) & " ± " & ROUNDUP(_xlfn.STDEV.S(P2:P151),0) -> 29 ± 22
A8: ATM_007_airways | B8: 1 | C8: 2 | D8: 4 | E8: 10 | F8: 14 | G8: 12 | H8: 4 | I8: 0 | J8: 0 | K8: 0 | L8: 0 | M8: 0 | O8: =CONCATENATE("G",MATCH(MAX(B8:K8),B8:K8,0)-1,"(",MAX(B8:K8),")") -> G4(14) | P8: =SUM(B8:K8) -> 47
A9: ATM_008_airways | B9: 1 | C9: 2 | D9: 4 | E9: 9 | F9: 15 | G9: 14 | H9: 6 | I9: 2 | J9: 1 | K9: 0 | L9: 0 | M9: 0 | O9: =CONCATENATE("G",MATCH(MAX(B9:K9),B9:K9,0)-1,"(",MAX(B9:K9),")") -> G4(15) | P9: =SUM(B9:K9) -> 54
A10: ATM_009_airways | B10: 1 | C10: 2 | D10: 4 | E10: 8 | F10: 7 | G10: 4 | H10: 0 | I10: 0 | J10: 0 | K10: 0 | L10: 0 | M10: 0 | O10: =CONCATENATE("G",MATCH(MAX(B10:K10),B10:K10,0)-1,"(",MAX(B10:K10),")") -> G3(8) | P10: =SUM(B10:K10) -> 26
A11: ATM_010_airways | B11: 1 | C11: 2 | D11: 4 | E11: 6 | F11: 6 | G11: 1 | H11: 0 | I11: 0 | J11: 0 | K11: 0 | L11: 0 | M11: 0 | O11: =CONCATENATE("G",MATCH(MAX(B11:K11),B11:K11,0)-1,"(",MAX(B11:K11),")") -> G3(6) | P11: =SUM(B11:K11) -> 20
A12: ATM_011_airways | B12: 1 | C12: 2 | D12: 4 | E12: 9 | F12: 19 | G12: 26 | H12: 6 | I12: 6 | J12: 4 | K12: 2 | L12: 0 | M12: 0 | O12: =CONCATENATE("G",MATCH(MAX(B12:K12),B12:K12,0)-1,"(",MAX(B12:K12),")") -> G5(26) | P12: =SUM(B12:K12) -> 79
A13: ATM_012_airways | B13: 1 | C13: 2 | D13: 4 | E13: 9 | F13: 7 | G13: 2 | H13: 0 | I13: 0 | J13: 0 | K13: 0 | L13: 0 | M13: 0 | O13: =CONCATENATE("G",MATCH(MAX(B13:K13),B13:K13,0)-1,"(",MAX(B13:K13),")") -> G3(9) | P13: =SUM(B13:K13) -> 25
A14: ATM_013_airways | B14: 1 | C14: 2 | D14: 4 | E14: 10 | F14: 14 | G14: 9 | H14: 8 | I14: 2 | J14: 2 | K14: 0 | L14: 0 | M14: 0 | O14: =CONCATENATE("G",MATCH(MAX(B14:K14),B14:K14,0)-1,"(",MAX(B14:K14),")") -> G4(14) | P14: =SUM(B14:K14) -> 52
A15: ATM_014_airways | B15: 1 | C15: 2 | D15: 4 | E15: 9 | F15: 12 | G15: 7 | H15: 0 | I15: 0 | J15: 0 | K15: 0 | L15: 0 | M15: 0 | O15: =CONCATENATE("G",MATCH(MAX(B15:K15),B15:K15,0)-1,"(",MAX(B15:K15),")") -> G4(12) | P15: =SUM(B15:K15) -> 35
A16: ATM_015_airways | B16: 0 | C16: 0 | D16: 0 | E16: 0 | F16: 0 | G16: 0 | H16: 0 | I16: 0 | J16: 0 | K16: 0 | L16: 0 | M16: 0 | O16: =CONCATENATE("G",MATCH(MAX(B16:K16),B16:K16,0)-1,"(",MAX(B16:K16),")") -> G0(0) | P16: =SUM(B16:K16) -> 0
A17: ATM_016_airways | B17: 1 | C17: 2 | D17: 4 | E17: 6 | F17: 6 | G17: 4 | H17: 2 | I17: 2 | J17: 0 | K17: 0 | L17: 0 | M17: 0 | O17: =CONCATENATE("G",MATCH(MAX(B17:K17),B17:K17,0)-1,"(",MAX(B17:K17),")") -> G3(6) | P17: =SUM(B17:K17) -> 27
A18: ATM_017_airways | B18: 1 | C18: 2 | D18: 5 | E18: 6 | F18: 4 | G18: 0 | H18: 0 | I18: 0 | J18: 0 | K18: 0 | L18: 0 | M18: 0 | O18: =CONCATENATE("G",MATCH(MAX(B18:K18),B18:K18,0)-1,"(",MAX(B18:K18),")") -> G3(6) | P18: =SUM(B18:K18) -> 18
A19: ATM_018_airways | B19: 1 | C19: 1 | D19: 2 | E19: 4 | F19: 8 | G19: 8 | H19: 1 | I19: 0 | J19: 0 | K19: 0 | L19: 0 | M19: 0 | O19: =CONCATENATE("G",MATCH(MAX(B19:K19),B19:K19,0)-1,"(",MAX(B19:K19),")") -> G4(8) | P19: =SUM(B19:K19) -> 25
... A151: ATM_172_airways | B151: 1 | C151: 2 | D151: 4 | E151: 9 | F151: 15 | G151: 6 | H151: 4 | I151: 4 | J151: 2 | K151: 0 | L151: 0 | M151: 0 | O151: =CONCATENATE("G",MATCH(MAX(B151:K151),B151:K151,0)-1,"(",MAX(B151:K151),")") -> G4(15) | P151: =SUM(B151:K151) -> 47

Sheet Clip_Pad
A1: Generaciones | B1: 0 | C1: 1 | D1: 2 | E1: 3 | F1: 4 | G1: 5 | H1: 6 | I1: 7 | J1: 8 | K1: 9 | L1: 10 | M1: 11 | O1: Peak | P1: TAC | S1: 0 | T1: 1 | U1: 2 | V1: 3 | W1: 4 | X1: 5 | Y1: 6 | Z1: 7 | AA1: 8 | AB1: 9 | AC1: 10 | AD1: 11
A2: ATM_001_airways | B2: 1 | C2: 2 | D2: 4 | E2: 7 | F2: 7 | G2: 2 | H2: 2 | I2: 4 | J2: 0 | K2: 0 | L2: 0 | M2: 0 | O2: =CONCATENATE("G",MATCH(MAX(B2:K2),B2:K2,0)-1,"(",MAX(B2:K2),")") -> G3(7) | P2: =SUM(B2:K2) -> 29 | R2: Promedio | S2: =ROUNDUP(AVERAGE(B2:B151), 0) -> 1 | T2: =ROUNDUP(AVERAGE(C2:C151), 0) -> 2 | U2: =ROUNDUP(AVERAGE(D2:D151), 0) -> 4 | V2: =ROUNDUP(AVERAGE(E2:E151), 0) -> 7 | W2: =ROUNDUP(AVERAGE(F2:F151), 0) -> 9 | X2: =ROUNDUP(AVERAGE(G2:G151), 0) -> 8 | Y2: =ROUNDUP(AVERAGE(H2:H151), 0) -> 5 | Z2: =ROUNDUP(AVERAGE(I2:I151), 0) -> 2 | ... AD2: =ROUNDUP(AVERAGE(M2:M151), 0) -> 0
A3: ATM_002_airways | B3: 1 | C3: 1 | D3: 2 | E3: 3 | F3: 8 | G3: 14 | H3: 12 | I3: 5 | J3: 4 | K3: 0 | L3: 0 | M3: 0 | O3: =CONCATENATE("G",MATCH(MAX(B3:K3),B3:K3,0)-1,"(",MAX(B3:K3),")") -> G5(14) | P3: =SUM(B3:K3) -> 50 | R3: Max | S3: =MAX(B2:B151) -> 2 | T3: =MAX(C2:C151) -> 3 | U3: =MAX(D2:D151) -> 5 | V3: =MAX(E2:E151) -> 11 | W3: =MAX(F2:F151) -> 21 | X3: =MAX(G2:G151) -> 35 | Y3: =MAX(H2:H151) -> 54 | Z3: =MAX(I2:I151) -> 15 | ... AD3: =MAX(M2:M151) -> 0
A4: ATM_003_airways | B4: 1 | C4: 2 | D4: 4 | E4: 8 | F4: 13 | G4: 10 | H4: 4 | I4: 0 | J4: 0 | K4: 0 | L4: 0 | M4: 0 | O4: =CONCATENATE("G",MATCH(MAX(B4:K4),B4:K4,0)-1,"(",MAX(B4:K4),")") -> G4(13) | P4: =SUM(B4:K4) -> 42 | R4: Moda | S4: =_xlfn.MODE.SNGL(B2:B151) -> 1 | T4: =_xlfn.MODE.SNGL(C2:C151) -> 2 | U4: =_xlfn.MODE.SNGL(D2:D151) -> 4 | V4: =_xlfn.MODE.SNGL(E2:E151) -> 9 | W4: =_xlfn.MODE.SNGL(F2:F151) -> 0 | X4: =_xlfn.MODE.SNGL(G2:G151) -> 0 | Y4: =_xlfn.MODE.SNGL(H2:H151) -> 0 | Z4: =_xlfn.MODE.SNGL(I2:I151) -> 0 | ... AD4: =_xlfn.MODE.SNGL(M2:M151) -> 0
A5: ATM_004_airways | B5: 1 | C5: 2 | D5: 3 | E5: 6 | F5: 12 | G5: 25 | H5: 23 | I5: 14 | J5: 6 | K5: 6 | L5: 0 | M5: 0 | O5: =CONCATENATE("G",MATCH(MAX(B5:K5),B5:K5,0)-1,"(",MAX(B5:K5),")") -> G5(25) | P5: =SUM(B5:K5) -> 98 | R5: Mediana | S5: =MEDIAN(B1:B151) -> 1 | T5: =MEDIAN(C1:C151) -> 2 | U5: =MEDIAN(D1:D151) -> 4 | V5: =MEDIAN(E1:E151) -> 7 | W5: =MEDIAN(F1:F151) -> 8 | X5: =MEDIAN(G1:G151) -> 6 | Y5: =MEDIAN(H1:H151) -> 2 | Z5: =MEDIAN(I1:I151) -> 0 | ... AD5: =MEDIAN(M1:M151) -> 0
A6: ATM_005_airways | B6: 1 | C6: 2 | D6: 4 | E6: 9 | F6: 15 | G6: 6 | H6: 2 | I6: 3 | J6: 0 | K6: 0 | L6: 0 | M6: 0 | O6: =CONCATENATE("G",MATCH(MAX(B6:K6),B6:K6,0)-1,"(",MAX(B6:K6),")") -> G4(15) | P6: =SUM(B6:K6) -> 42 | S6: TAC
A7: ATM_006_airways | B7: 1 | C7: 2 | D7: 4 | E7: 9 | F7: 17 | G7: 19 | H7: 13 | I7: 8 | J7: 1 | K7: 0 | L7: 0 | M7: 0 | O7: =CONCATENATE("G",MATCH(MAX(B7:K7),B7:K7,0)-1,"(",MAX(B7:K7),")") -> G5(19) | P7: =SUM(B7:K7) -> 74 | R7: Promedio | S7: =ROUNDUP(AVERAGE(P2:P151),0) & " ± " & ROUNDUP(_xlfn.STDEV.S(P2:P151),0) -> 37 ± 24
A8: ATM_007_airways | B8: 1 | C8: 2 | D8: 4 | E8: 10 | F8: 16 | G8: 16 | H8: 54 | I8: 0 | J8: 0 | K8: 0 | L8: 0 | M8: 0 | O8: =CONCATENATE("G",MATCH(MAX(B8:K8),B8:K8,0)-1,"(",MAX(B8:K8),")") -> G6(54) | P8: =SUM(B8:K8) -> 103
A9: ATM_008_airways | B9: 1 | C9: 2 | D9: 4 | E9: 9 | F9: 19 | G9: 15 | H9: 15 | I9: 6 | J9: 0 | K9: 0 | L9: 0 | M9: 0 | O9: =CONCATENATE("G",MATCH(MAX(B9:K9),B9:K9,0)-1,"(",MAX(B9:K9),")") -> G4(19) | P9: =SUM(B9:K9) -> 71
A10: ATM_009_airways | B10: 1 | C10: 2 | D10: 4 | E10: 7 | F10: 6 | G10: 0 | H10: 0 | I10: 0 | J10: 0 | K10: 0 | L10: 0 | M10: 0 | O10: =CONCATENATE("G",MATCH(MAX(B10:K10),B10:K10,0)-1,"(",MAX(B10:K10),")") -> G3(7) | P10: =SUM(B10:K10) -> 20
A11: ATM_010_airways | B11: 1 | C11: 1 | D11: 2 | E11: 4 | F11: 6 | G11: 6 | H11: 2 | I11: 0 | J11: 0 | K11: 0 | L11: 0 | M11: 0 | O11: =CONCATENATE("G",MATCH(MAX(B11:K11),B11:K11,0)-1,"(",MAX(B11:K11),")") -> G4(6) | P11: =SUM(B11:K11) -> 22
A12: ATM_011_airways | B12: 1 | C12: 2 | D12: 4 | E12: 10 | F12: 20 | G12: 33 | H12: 13 | I12: 6 | J12: 2 | K12: 0 | L12: 0 | M12: 0 | O12: =CONCATENATE("G",MATCH(MAX(B12:K12),B12:K12,0)-1,"(",MAX(B12:K12),")") -> G5(33) | P12: =SUM(B12:K12) -> 91
A13: ATM_012_airways | B13: 1 | C13: 2 | D13: 4 | E13: 9 | F13: 5 | G13: 2 | H13: 0 | I13: 0 | J13: 0 | K13: 0 | L13: 0 | M13: 0 | O13: =CONCATENATE("G",MATCH(MAX(B13:K13),B13:K13,0)-1,"(",MAX(B13:K13),")") -> G3(9) | P13: =SUM(B13:K13) -> 23
A14: ATM_013_airways | B14: 1 | C14: 2 | D14: 4 | E14: 9 | F14: 15 | G14: 16 | H14: 10 | I14: 2 | J14: 0 | K14: 0 | L14: 0 | M14: 0 | O14: =CONCATENATE("G",MATCH(MAX(B14:K14),B14:K14,0)-1,"(",MAX(B14:K14),")") -> G5(16) | P14: =SUM(B14:K14) -> 59
A15: ATM_014_airways | B15: 1 | C15: 2 | D15: 4 | E15: 5 | F15: 0 | G15: 0 | H15: 0 | I15: 0 | J15: 0 | K15: 0 | L15: 0 | M15: 0 | O15: =CONCATENATE("G",MATCH(MAX(B15:K15),B15:K15,0)-1,"(",MAX(B15:K15),")") -> G3(5) | P15: =SUM(B15:K15) -> 12
A16: ATM_015_airways | B16: 1 | C16: 2 | D16: 4 | E16: 5 | F16: 0 | G16: 0 | H16: 0 | I16: 0 | J16: 0 | K16: 0 | L16: 0 | M16: 0 | O16: =CONCATENATE("G",MATCH(MAX(B16:K16),B16:K16,0)-1,"(",MAX(B16:K16),")") -> G3(5) | P16: =SUM(B16:K16) -> 12
A17: ATM_016_airways | B17: 1 | C17: 2 | D17: 4 | E17: 9 | F17: 19 | G17: 8 | H17: 2 | I17: 2 | J17: 0 | K17: 0 | L17: 0 | M17: 0 | O17: =CONCATENATE("G",MATCH(MAX(B17:K17),B17:K17,0)-1,"(",MAX(B17:K17),")") -> G4(19) | P17: =SUM(B17:K17) -> 47
A18: ATM_017_airways | B18: 1 | C18: 2 | D18: 4 | E18: 9 | F18: 7 | G18: 3 | H18: 0 | I18: 0 | J18: 0 | K18: 0 | L18: 0 | M18: 0 | O18: =CONCATENATE("G",MATCH(MAX(B18:K18),B18:K18,0)-1,"(",MAX(B18:K18),")") -> G3(9) | P18: =SUM(B18:K18) -> 26
A19: ATM_018_airways | B19: 1 | C19: 1 | D19: 2 | E19: 4 | F19: 9 | G19: 11 | H19: 3 | I19: 0 | J19: 0 | K19: 0 | L19: 0 | M19: 0 | O19: =CONCATENATE("G",MATCH(MAX(B19:K19),B19:K19,0)-1,"(",MAX(B19:K19),")") -> G5(11) | P19: =SUM(B19:K19) -> 31
... A151: ATM_172_airways | B151: 0 | C151: 0 | D151: 0 | E151: 0 | F151: 0 | G151: 0 | H151: 0 | I151: 0 | J151: 0 | K151: 0 | L151: 0 | M151: 0 | O151: =CONCATENATE("G",MATCH(MAX(B151:K151),B151:K151,0)-1,"(",MAX(B151:K151),")") -> G0(0) | P151: =SUM(B151:K151) -> 0

Sheet Smo_Norm
A1: Generaciones | B1: 0 | C1: 1 | D1: 2 | E1: 3 | F1: 4 | G1: 5 | H1: 6 | I1: 7 | J1: 8 | K1: 9 | L1: 10 | M1: 11 | O1: Peak | P1: TAC | S1: 0 | T1: 1 | U1: 2 | V1: 3 | W1: 4 | X1: 5 | Y1: 6 | Z1: 7 | AA1: 8 | AB1: 9 | AC1: 10 | AD1: 11
A2: ATM_001_airways | B2: 1 | C2: 2 | D2: 4 | E2: 8 | F2: 8 | G2: 2 | H2: 0 | I2: 0 | J2: 0 | K2: 0 | L2: 0 | M2: 0 | O2: =CONCATENATE("G",MATCH(MAX(B2:K2),B2:K2,0)-1,"(",MAX(B2:K2),")") -> G3(8) | P2: =SUM(B2:K2) -> 25 | R2: Promedio | S2: =ROUNDUP(AVERAGE(B2:B151), 0) -> 1 | T2: =ROUNDUP(AVERAGE(C2:C151), 0) -> 2 | U2: =ROUNDUP(AVERAGE(D2:D151), 0) -> 4 | V2: =ROUNDUP(AVERAGE(E2:E151), 0) -> 5 | W2: =ROUNDUP(AVERAGE(F2:F151), 0) -> 4 | X2: =ROUNDUP(AVERAGE(G2:G151), 0) -> 2 | Y2: =ROUNDUP(AVERAGE(H2:H151), 0) -> 1 | Z2: =ROUNDUP(AVERAGE(I2:I151), 0) -> 1 | ... AD2: =ROUNDUP(AVERAGE(M2:M151), 0) -> 0
A3: ATM_002_airways | B3: 1 | C3: 2 | D3: 2 | E3: 4 | F3: 2 | G3: 0 | H3: 0 | I3: 0 | J3: 0 | K3: 0 | L3: 0 | M3: 0 | O3: =CONCATENATE("G",MATCH(MAX(B3:K3),B3:K3,0)-1,"(",MAX(B3:K3),")") -> G3(4) | P3: =SUM(B3:K3) -> 11 | R3: Max | S3: =MAX(B2:B151) -> 2 | T3: =MAX(C2:C151) -> 3 | U3: =MAX(D2:D151) -> 5 | V3: =MAX(E2:E151) -> 10 | W3: =MAX(F2:F151) -> 18 | X3: =MAX(G2:G151) -> 18 | Y3: =MAX(H2:H151) -> 6 | Z3: =MAX(I2:I151) -> 6 | ... AD3: =MAX(M2:M151) -> 0
A4: ATM_003_airways | B4: 1 | C4: 2 | D4: 4 | E4: 6 | F4: 2 | G4: 0 | H4: 0 | I4: 0 | J4: 0 | K4: 0 | L4: 0 | M4: 0 | O4: =CONCATENATE("G",MATCH(MAX(B4:K4),B4:K4,0)-1,"(",MAX(B4:K4),")") -> G3(6) | P4: =SUM(B4:K4) -> 15 | R4: Moda | S4: =_xlfn.MODE.SNGL(B2:B151) -> 1 | T4: =_xlfn.MODE.SNGL(C2:C151) -> 2 | U4: =_xlfn.MODE.SNGL(D2:D151) -> 4 | V4: =_xlfn.MODE.SNGL(E2:E151) -> 4 | W4: =_xlfn.MODE.SNGL(F2:F151) -> 0 | X4: =_xlfn.MODE.SNGL(G2:G151) -> 0 | Y4: =_xlfn.MODE.SNGL(H2:H151) -> 0 | Z4: =_xlfn.MODE.SNGL(I2:I151) -> 0 | ... AD4: =_xlfn.MODE.SNGL(M2:M151) -> 0
A5: ATM_004_airways | B5: 1 | C5: 2 | D5: 4 | E5: 8 | F5: 14 | G5: 9 | H5: 0 | I5: 0 | J5: 0 | K5: 0 | L5: 0 | M5: 0 | O5: =CONCATENATE("G",MATCH(MAX(B5:K5),B5:K5,0)-1,"(",MAX(B5:K5),")") -> G4(14) | P5: =SUM(B5:K5) -> 38 | R5: Mediana | S5: =MEDIAN(B1:B151) -> 1 | T5: =MEDIAN(C1:C151) -> 2 | U5: =MEDIAN(D1:D151) -> 4 | V5: =MEDIAN(E1:E151) -> 4 | W5: =MEDIAN(F1:F151) -> 3 | X5: =MEDIAN(G1:G151) -> 0 | Y5: =MEDIAN(H1:H151) -> 0 | Z5: =MEDIAN(I1:I151) -> 0 | ... AD5: =MEDIAN(M1:M151) -> 0
A6: ATM_005_airways | B6: 1 | C6: 2 | D6: 4 | E6: 1 | F6: 2 | G6: 0 | H6: 0 | I6: 0 | J6: 0 | K6: 0 | L6: 0 | M6: 0 | O6: =CONCATENATE("G",MATCH(MAX(B6:K6),B6:K6,0)-1,"(",MAX(B6:K6),")") -> G2(4) | P6: =SUM(B6:K6) -> 10 | S6: TAC
A7: ATM_006_airways | B7: 1 | C7: 2 | D7: 4 | E7: 8 | F7: 4 | G7: 5 | H7: 0 | I7: 0 | J7: 0 | K7: 0 | L7: 0 | M7: 0 | O7: =CONCATENATE("G",MATCH(MAX(B7:K7),B7:K7,0)-1,"(",MAX(B7:K7),")") -> G3(8) | P7: =SUM(B7:K7) -> 24 | R7: Promedio | S7: =ROUNDUP(AVERAGE(P2:P151),0) & " ± " & ROUNDUP(_xlfn.STDEV.S(P2:P151),0) -> 17 ± 12
A8: ATM_007_airways | B8: 1 | C8: 2 | D8: 4 | E8: 10 | F8: 11 | G8: 2 | H8: 2 | I8: 0 | J8: 0 | K8: 0 | L8: 0 | M8: 0 | O8: =CONCATENATE("G",MATCH(MAX(B8:K8),B8:K8,0)-1,"(",MAX(B8:K8),")") -> G4(11) | P8: =SUM(B8:K8) -> 32
A9: ATM_008_airways | B9: 1 | C9: 2 | D9: 4 | E9: 9 | F9: 10 | G9: 2 | H9: 0 | I9: 0 | J9: 0 | K9: 0 | L9: 0 | M9: 0 | O9: =CONCATENATE("G",MATCH(MAX(B9:K9),B9:K9,0)-1,"(",MAX(B9:K9),")") -> G4(10) | P9: =SUM(B9:K9) -> 28
A10: ATM_009_airways | B10: 1 | C10: 1 | D10: 2 | E10: 4 | F10: 5 | G10: 0 | H10: 0 | I10: 0 | J10: 0 | K10: 0 | L10: 0 | M10: 0 | O10: =CONCATENATE("G",MATCH(MAX(B10:K10),B10:K10,0)-1,"(",MAX(B10:K10),")") -> G4(5) | P10: =SUM(B10:K10) -> 13
A11: ATM_010_airways | B11: 1 | C11: 2 | D11: 4 | E11: 8 | F11: 3 | G11: 0 | H11: 0 | I11: 0 | J11: 0 | K11: 0 | L11: 0 | M11: 0 | O11: =CONCATENATE("G",MATCH(MAX(B11:K11),B11:K11,0)-1,"(",MAX(B11:K11),")") -> G3(8) | P11: =SUM(B11:K11) -> 18
A12: ATM_011_airways | B12: 1 | C12: 2 | D12: 4 | E12: 8 | F12: 14 | G12: 16 | H12: 3 | I12: 2 | J12: 4 | K12: 0 | L12: 0 | M12: 0 | O12: =CONCATENATE("G",MATCH(MAX(B12:K12),B12:K12,0)-1,"(",MAX(B12:K12),")") -> G5(16) | P12: =SUM(B12:K12) -> 54
A13: ATM_012_airways | B13: 1 | C13: 1 | D13: 2 | E13: 4 | F13: 3 | G13: 2 | H13: 0 | I13: 0 | J13: 0 | K13: 0 | L13: 0 | M13: 0 | O13: =CONCATENATE("G",MATCH(MAX(B13:K13),B13:K13,0)-1,"(",MAX(B13:K13),")") -> G3(4) | P13: =SUM(B13:K13) -> 13
A14: ATM_013_airways | B14: 1 | C14: 2 | D14: 4 | E14: 9 | F14: 4 | G14: 2 | H14: 1 | I14: 0 | J14: 0 | K14: 0 | L14: 0 | M14: 0 | O14: =CONCATENATE("G",MATCH(MAX(B14:K14),B14:K14,0)-1,"(",MAX(B14:K14),")") -> G3(9) | P14: =SUM(B14:K14) -> 23
